Workbook

Sheet INICIO
A1: CONTROL ADMINISTRATIVO – RESTAURANTE / HELADERÍA
A2: Inventario, costos, recetas, planilla, gastos, caja y reportes en un solo libro.
B4: Negocio: | C4: =NEGOCIO -> La Cremería
B6: CÓMO LEER LOS COLORES
B7: Azul claro, letra azul | C7: Celda para LLENAR por usted (datos de entrada).
B8: Gris | C8: Se calcula sola. No la escriba (tiene fórmula).
B9: Letra verde | C9: Viene de otra hoja (enlace).
B10: Amarillo | C10: Resultado o supuesto clave.
B12: ORDEN DE USO
B13: CONFIG | C13: 1 sola vez: nombre, año, % IVA, cargas sociales CCSS/INS, márgenes objetivo y listas desplegables.
B14: INSUMOS | C14: Catálogo de materias primas y empaques: presentación de compra, precio, % aprovechamiento, stock mínimo e inicial. Aquí ve el INVENTARIO ACTUAL, su valor y qué reordenar.
B15: COMPRAS | C15: Registre cada factura de proveedor. Suma al inventario y actualiza el último costo del insumo. Controle pendientes de pago.
B16: RECETAS | C16: Una línea por ingrediente de cada producto (cantidad neta por porción o por lote). Calcula el costo de cada receta.
B17: FICHA_TECNICA | C17: Elija un producto y vea su ficha técnica: ingredientes, costo, margen, precio sugerido y preparación.
B18: PRODUCTOS | C18: Menú con precio de venta (con IVA). Calcula costo variable, contribución, food cost y precio sugerido.
B19: VENTAS | C19: Registre ventas (por ticket o total diario por producto). Descuenta el inventario según las recetas.
B20: MERMAS | C20: Mermas, vencidos, cortesías y ajustes de conteo físico. Afectan inventario y resultados.
B21: PLANILLA | C21: Planilla mensual: salario, horas extra, CCSS obrera/patronal, INS, aguinaldo, vacaciones, cesantía.
B22: GASTOS | C22: Gastos operativos (alquiler, luz, agua, internet, publicidad, contador, etc.).
B23: CAJA_DIARIA | C23: Cierre de caja: fondo, ventas por medio de pago, efectivo esperado vs contado, faltantes/sobrantes.
B24: ESTADO_RESULTADOS | C24: Automático: ventas, costo de ventas, utilidad, planilla, gastos, indicadores e IVA por mes.
... B27: DASHBOARD | C27: Resumen del mes elegido: KPIs, productos más rentables, insumos por reordenar y gráfico anual.
B29: REGLAS DE ORO
B30: • | C30: Precios de venta con IVA en PRODUCTOS; los análisis usan el precio NETO (sin IVA), como en la capacitación.
B31: • | C31: Las recetas usan cantidades NETAS aprovechables (g, ml o unidades). El % de aprovechamiento convierte a cantidad bruta comprada.
B32: • | C32: La planilla fija va una sola vez (en PLANILLA), nunca dentro del costo de las recetas.
B33: • | C33: Use el mismo período en todo y no duplique costos (p. ej., no meta en GASTOS lo que ya está en COMPRAS de insumos).
B34: • | C34: Haga un conteo físico al menos semanal en INSUMOS (columna 'Conteo físico') para detectar faltantes.
B35: • | C35: Los datos que trae el libro son EJEMPLOS ilustrativos: bórrelos o reemplácelos por los suyos. Verifique tasas CCSS/INS/renta vigentes con su contador.

Sheet CONFIG
A1: CONFIGURACIÓN Y PARÁMETROS
A2: Llene las celdas azules. Las demás hojas usan estos valores por su nombre (p. ej. IVA_VENTAS).
F4: LISTAS DESPLEGABLES (puede agregar opciones en las celdas azules vacías)
B5: Parámetro | C5: Valor | D5: Nota / fuente | F5: Categorías de insumo | G5: Unidades base | H5: Categorías de gasto | I5: Medios de pago | J5: Movimientos de inventario | K5: Canales de venta | L5: Forma de pago compras | M5: Estado de pago | N5: Tipo de gasto | O5: Categorías de producto
B6: Nombre del negocio | C6: La Cremería | D6: Aparece en reportes. | F6: Fruta | G6: g | H6: Alquiler | I6: Efectivo | J6: Merma | K6: Local | L6: Contado | M6: Pagado | N6: Fijo | O6: Fresas con crema
B7: Año del estado de resultados | C7: 2026 | D7: Columnas ene–dic de ESTADO_RESULTADOS. | F7: Lácteos | G7: ml | H7: Electricidad | I7: SINPE Móvil | J7: Vencimiento | K7: Para llevar | L7: Crédito | M7: Pendiente | N7: Variable | O7: Especiales
B8: Mes a analizar en el DASHBOARD | C8: 46296 | D8: Escriba el día 1 del mes. | F8: Abarrotes | G8: u | H8: Agua | I8: Tarjeta | J8: Daño | K8: WhatsApp | O8: Extras
B9: IVA en ventas | C9: 0.13 | D9: Tarifa general CR 13%. Se usa como valor por defecto en PRODUCTOS. | F9: Toppings | H9: Internet y teléfono | I9: Plataforma | J9: Consumo interno | K9: Delivery | O9: Postres
B10: IVA promedio en compras de insumos | C10: 0.05 | D10: Supuesto para el flujo de caja (mezcla canasta básica 1% y 13%). | F10: Jarabes y salsas | H10: Gas | I10: Transferencia | J10: Cortesía | O10: Bebidas
B11: CCSS cuota patronal | C11: 0.265 | D11: Valor usado en la capacitación (26.50%). Verifique la tasa vigente. | F11: Empaque | H11: Publicidad y redes | J11: Ajuste (-) faltante
B12: CCSS cuota obrera (rebajo al trabajador) | C12: 0.1067 | D12: Supuesto. Verifique la tasa vigente. | F12: Limpieza | H12: Servicios profesionales | J12: Ajuste (+) sobrante
B13: Póliza riesgos del trabajo (INS) | C13: 0.0185 | D13: Valor de la capacitación (1.85%). Depende de su póliza. | F13: Otros | H13: Mantenimiento y reparaciones
B14: Provisión aguinaldo | C14: 0.0833 | D14: 1/12 del salario. | H14: Limpieza
B15: Provisión vacaciones | C15: 0.0416 | D15: Valor de la capacitación (4.16%). | H15: Patentes, permisos y seguros
B16: Provisión cesantía / despidos | C16: 0.0533 | D16: Valor de la capacitación (5.33%). | H16: Comisiones tarjetas/plataformas
B17: Recargo hora extra (x salario/hora) | C17: 1.5 | D17: Tiempo y medio. | H17: Transporte y combustible
B18: Horas base por mes (salario/hora) | C18: 240 | D18: 30 días x 8 horas. | H18: Otros gastos
B19: Imprevistos en flujo de caja | C19: 0.05 | D19: Valor de la capacitación (5%).
B20: Impuesto sobre la renta estimado | C20: 0.15 | D20: Supuesto de la capacitación. Persona jurídica PYME / física tiene tramos: confirme con su contador.
B21: Margen de contribución objetivo | C21: 0.65 | D21: Para precio sugerido = costo ÷ (1 − margen).
B22: Food cost máximo aceptable | C22: 0.35 | D22: Si un producto lo supera se marca 'REVISAR PRECIO'.
B23: Días de operación por mes | C23: 26 | D23: Para venta diaria necesaria.
B24: Efectivo inicial en banco (flujo) | C24: 1500000 | D24: Saldo al inicio del flujo de caja.
B25: Mes de inicio del flujo de caja | C25: 46327 | D25: Día 1 del primer mes proyectado.
B26: Crecimiento mensual de ventas (flujo) | C26: 0.02 | D26: Supuesto de proyección.
B27: Meses de gastos fijos como reserva mínima | C27: 1 | D27: Si el saldo baja de esto, el flujo alerta.

Sheet DASHBOARD
A1: DASHBOARD DEL MES
A2: Cambie el mes en CONFIG → 'Mes a analizar en el DASHBOARD'.
B4: =NEGOCIO -> La Cremería | C4: =MES_REPORTE -> 46296 | F4: Meta food cost ≤ | G4: =FOODCOST_MAX -> 0.35
B5: Resultados | E5: Indicadores | H5: Control
B6: Ventas netas | C6: =IFERROR(INDEX(ESTADO_RESULTADOS!$C$9:$N$9,MATCH(MES_REPORTE,ESTADO_RESULTADOS!$C$5:$N$5,0)),0) -> 342212.39 | E6: Food cost % | F6: =IFERROR(INDEX(ESTADO_RESULTADOS!$C$37:$N$37,MATCH(MES_REPORTE,ESTADO_RESULTADOS!$C$5:$N$5,0)),0) -> 0.35242938 | H6: Valor del inventario hoy | I6: =SUM(INSUMOS!$U$6:$U$205) -> 388439.3
B7: Costo de ventas | C7: =IFERROR(INDEX(ESTADO_RESULTADOS!$C$10:$N$10,MATCH(MES_REPORTE,ESTADO_RESULTADOS!$C$5:$N$5,0)),0) -> 120605.7 | E7: Labor cost % | F7: =IFERROR(INDEX(ESTADO_RESULTADOS!$C$38:$N$38,MATCH(MES_REPORTE,ESTADO_RESULTADOS!$C$5:$N$5,0)),0) -> 4.9376506 | H7: Insumos por reordenar / agotados | I7: =COUNTIF(INSUMOS!$Y$6:$Y$205,"REORDENAR")+COUNTIF(INSUMOS!$Y$6:$Y$205,"AGOTADO") -> 1
B8: Utilidad bruta | C8: =IFERROR(INDEX(ESTADO_RESULTADOS!$C$11:$N$11,MATCH(MES_REPORTE,ESTADO_RESULTADOS!$C$5:$N$5,0)),0) -> 221606.69 | E8: Prime cost % | F8: =IFERROR(INDEX(ESTADO_RESULTADOS!$C$39:$N$39,MATCH(MES_REPORTE,ESTADO_RESULTADOS!$C$5:$N$5,0)),0) -> 5.2900799 | H8: Diferencias de conteo físico (₡) | I8: =SUM(INSUMOS!$X$6:$X$205) -> 0
B9: Gastos de operación (incl. planilla) | C9: =IFERROR(INDEX(ESTADO_RESULTADOS!$C$31:$N$31,MATCH(MES_REPORTE,ESTADO_RESULTADOS!$C$5:$N$5,0)),0) -> 2372680.2 | E9: Margen operativo % | F9: =IFERROR(INDEX(ESTADO_RESULTADOS!$C$33:$N$33,MATCH(MES_REPORTE,ESTADO_RESULTADOS!$C$5:$N$5,0)),0) -> -6.285785 | H9: Compras pendientes de pago | I9: =SUMIFS(COMPRAS!$M$6:$M$1005,COMPRAS!$P$6:$P$1005,"Pendiente") -> 51246
B10: UTILIDAD OPERATIVA | C10: =IFERROR(INDEX(ESTADO_RESULTADOS!$C$32:$N$32,MATCH(MES_REPORTE,ESTADO_RESULTADOS!$C$5:$N$5,0)),0) -> -2151073.5 | E10: IVA neto por pagar (estimado) | F10: =IFERROR(INDEX(ESTADO_RESULTADOS!$C$43:$N$43,MATCH(MES_REPORTE,ESTADO_RESULTADOS!$C$5:$N$5,0)),0) -> -49695.389 | H10: Productos con precio a revisar | I10: =COUNTIF(PRODUCTOS!$R$6:$R$105,"REVISAR PRECIO") -> 6
B12: Productos en el mes
B13: Producto | C13: Unidades | E13: Venta neta | F13: Contribución | H13: % de la contribución total | I13: Margen %
B14: =IF(PRODUCTOS!$A$6="","",PRODUCTOS!$B$6) -> Fresas con crema Pequeño (8 oz) | C14: =IF(PRODUCTOS!$A$6="","",SUMIFS(VENTAS!$E$6:$E$2005,VENTAS!$C$6:$C$2005,PRODUCTOS!$A$6,VENTAS!$O$6:$O$2005,MES_REPORTE)) -> 27 | E14: =IF(PRODUCTOS!$A$6="","",SUMIFS(VENTAS!$J$6:$J$2005,VENTAS!$C$6:$C$2005,PRODUCTOS!$A$6,VENTAS!$O$6:$O$2005,MES_REPORTE)) -> 46592.92 | F14: =IF(PRODUCTOS!$A$6="","",SUMIFS(VENTAS!$L$6:$L$2005,VENTAS!$C$6:$C$2005,PRODUCTOS!$A$6,VENTAS!$O$6:$O$2005,MES_REPORTE)) -> 28411.938 | H14: =IF(PRODUCTOS!$A$6="","",IFERROR(F14/SUM($F$14:$F$33),0)) -> 0.12820885 | I14: =IF(PRODUCTOS!$A$6="","",IFERROR(F14/E14,0)) -> 0.60979088
B15: =IF(PRODUCTOS!$A$7="","",PRODUCTOS!$B$7) -> Fresas con crema Mediano (12 oz) | C15: =IF(PRODUCTOS!$A$7="","",SUMIFS(VENTAS!$E$6:$E$2005,VENTAS!$C$6:$C$2005,PRODUCTOS!$A$7,VENTAS!$O$6:$O$2005,MES_REPORTE)) -> 40 | E15: =IF(PRODUCTOS!$A$7="","",SUMIFS(VENTAS!$J$6:$J$2005,VENTAS!$C$6:$C$2005,PRODUCTOS!$A$7,VENTAS!$O$6:$O$2005,MES_REPORTE)) -> 104424.78 | F15: =IF(PRODUCTOS!$A$7="","",SUMIFS(VENTAS!$L$6:$L$2005,VENTAS!$C$6:$C$2005,PRODUCTOS!$A$7,VENTAS!$O$6:$O$2005,MES_REPORTE)) -> 64299.357 | H15: =IF(PRODUCTOS!$A$7="","",IFERROR(F15/SUM($F$14:$F$33),0)) -> 0.29015079 | I15: =IF(PRODUCTOS!$A$7="","",IFERROR(F15/E15,0)) -> 0.61574808
B16: =IF(PRODUCTOS!$A$8="","",PRODUCTOS!$B$8) -> Fresas con crema Grande (16 oz) | C16: =IF(PRODUCTOS!$A$8="","",SUMIFS(VENTAS!$E$6:$E$2005,VENTAS!$C$6:$C$2005,PRODUCTOS!$A$8,VENTAS!$O$6:$O$2005,MES_REPORTE)) -> 20 | E16: =IF(PRODUCTOS!$A$8="","",SUMIFS(VENTAS!$J$6:$J$2005,VENTAS!$C$6:$C$2005,PRODUCTOS!$A$8,VENTAS!$O$6:$O$2005,MES_REPORTE)) -> 87610.619 | F16: =IF(PRODUCTOS!$A$8="","",SUMIFS(VENTAS!$L$6:$L$2005,VENTAS!$C$6:$C$2005,PRODUCTOS!$A$8,VENTAS!$O$6:$O$2005,MES_REPORTE)) -> 57112.994 | H16: =IF(PRODUCTOS!$A$8="","",IFERROR(F16/SUM($F$14:$F$33),0)) -> 0.25772234 | I16: =IF(PRODUCTOS!$A$8="","",IFERROR(F16/E16,0)) -> 0.65189579
B17: =IF(PRODUCTOS!$A$9="","",PRODUCTOS!$B$9) -> Fresas con crema Extra grande (24 oz) | C17: =IF(PRODUCTOS!$A$9="","",SUMIFS(VENTAS!$E$6:$E$2005,VENTAS!$C$6:$C$2005,PRODUCTOS!$A$9,VENTAS!$O$6:$O$2005,MES_REPORTE)) -> 7 | E17: =IF(PRODUCTOS!$A$9="","",SUMIFS(VENTAS!$J$6:$J$2005,VENTAS!$C$6:$C$2005,PRODUCTOS!$A$9,VENTAS!$O$6:$O$2005,MES_REPORTE)) -> 43053.097 | F17: =IF(PRODUCTOS!$A$9="","",SUMIFS(VENTAS!$L$6:$L$2005,VENTAS!$C$6:$C$2005,PRODUCTOS!$A$9,VENTAS!$O$6:$O$2005,MES_REPORTE)) -> 26601.182 | H17: =IF(PRODUCTOS!$A$9="","",IFERROR(F17/SUM($F$14:$F$33),0)) -> 0.12003781 | I17: =IF(PRODUCTOS!$A$9="","",IFERROR(F17/E17,0)) -> 0.61786919
B18: =IF(PRODUCTOS!$A$10="","",PRODUCTOS!$B$10) -> Maracumango | C18: =IF(PRODUCTOS!$A$10="","",SUMIFS(VENTAS!$E$6:$E$2005,VENTAS!$C$6:$C$2005,PRODUCTOS!$A$10,VENTAS!$O$6:$O$2005,MES_REPORTE)) -> 13 | E18: =IF(PRODUCTOS!$A$10="","",SUMIFS(VENTAS!$J$6:$J$2005,VENTAS!$C$6:$C$2005,PRODUCTOS!$A$10,VENTAS!$O$6:$O$2005,MES_REPORTE)) -> 48318.584 | F18: =IF(PRODUCTOS!$A$10="","",SUMIFS(VENTAS!$L$6:$L$2005,VENTAS!$C$6:$C$2005,PRODUCTOS!$A$10,VENTAS!$O$6:$O$2005,MES_REPORTE)) -> 36509.646 | H18: =IF(PRODUCTOS!$A$10="","",IFERROR(F18/SUM($F$14:$F$33),0)) -> 0.16474975 | I18: =IF(PRODUCTOS!$A$10="","",IFERROR(F18/E18,0)) -> 0.75560257
B19: =IF(PRODUCTOS!$A$11="","",PRODUCTOS!$B$11) -> Topping extra | C19: =IF(PRODUCTOS!$A$11="","",SUMIFS(VENTAS!$E$6:$E$2005,VENTAS!$C$6:$C$2005,PRODUCTOS!$A$11,VENTAS!$O$6:$O$2005,MES_REPORTE)) -> 8 | E19: =IF(PRODUCTOS!$A$11="","",SUMIFS(VENTAS!$J$6:$J$2005,VENTAS!$C$6:$C$2005,PRODUCTOS!$A$11,VENTAS!$O$6:$O$2005,MES_REPORTE)) -> 1415.9292 | F19: =IF(PRODUCTOS!$A$11="","",SUMIFS(VENTAS!$L$6:$L$2005,VENTAS!$C$6:$C$2005,PRODUCTOS!$A$11,VENTAS!$O$6:$O$2005,MES_REPORTE)) -> 655.69529 | H19: =IF(PRODUCTOS!$A$11="","",IFERROR(F19/SUM($F$14:$F$33),0)) -> 0.0029588244 | I19: =IF(PRODUCTOS!$A$11="","",IFERROR(F19/E19,0)) -> 0.4630848
B20: =IF(PRODUCTOS!$A$12="","",PRODUCTOS!$B$12) -> Topping extra premium | C20: =IF(PRODUCTOS!$A$12="","",SUMIFS(VENTAS!$E$6:$E$2005,VENTAS!$C$6:$C$2005,PRODUCTOS!$A$12,VENTAS!$O$6:$O$2005,MES_REPORTE)) -> 4 | E20: =IF(PRODUCTOS!$A$12="","",SUMIFS(VENTAS!$J$6:$J$2005,VENTAS!$C$6:$C$2005,PRODUCTOS!$A$12,VENTAS!$O$6:$O$2005,MES_REPORTE)) -> 1061.9469 | F20: =IF(PRODUCTOS!$A$12="","",SUMIFS(VENTAS!$L$6:$L$2005,VENTAS!$C$6:$C$2005,PRODUCTOS!$A$12,VENTAS!$O$6:$O$2005,MES_REPORTE)) -> 491.9469 | H20: =IF(PRODUCTOS!$A$12="","",IFERROR(F20/SUM($F$14:$F$33),0)) -> 0.00221991 | I20: =IF(PRODUCTOS!$A$12="","",IFERROR(F20/E20,0)) -> 0.46325
B21: =IF(PRODUCTOS!$A$13="","",PRODUCTOS!$B$13) -> Jarabe premium (Nutella / pistacho) | C21: =IF(PRODUCTOS!$A$13="","",SUMIFS(VENTAS!$E$6:$E$2005,VENTAS!$C$6:$C$2005,PRODUCTOS!$A$13,VENTAS!$O$6:$O$2005,MES_REPORTE)) -> 5 | E21: =IF(PRODUCTOS!$A$13="","",SUMIFS(VENTAS!$J$6:$J$2005,VENTAS!$C$6:$C$2005,PRODUCTOS!$A$13,VENTAS!$O$6:$O$2005,MES_REPORTE)) -> 1769.9115 | F21: =IF(PRODUCTOS!$A$13="","",SUMIFS(VENTAS!$L$6:$L$2005,VENTAS!$C$6:$C$2005,PRODUCTOS!$A$13,VENTAS!$O$6:$O$2005,MES_REPORTE)) -> 576.92905 | H21: =IF(PRODUCTOS!$A$13="","",IFERROR(F21/SUM($F$14:$F$33),0)) -> 0.0026033918 | I21: =IF(PRODUCTOS!$A$13="","",IFERROR(F21/E21,0)) -> 0.32596491
B22: =IF(PRODUCTOS!$A$14="","",PRODUCTOS!$B$14) -> Brownie de la casa (lote de 20) | C22: =IF(PRODUCTOS!$A$14="","",SUMIFS(VENTAS!$E$6:$E$2005,VENTAS!$C$6:$C$2005,PRODUCTOS!$A$14,VENTAS!$O$6:$O$2005,MES_REPORTE)) -> 6 | E22: =IF(PRODUCTOS!$A$14="","",SUMIFS(VENTAS!$J$6:$J$2005,VENTAS!$C$6:$C$2005,PRODUCTOS!$A$14,VENTAS!$O$6:$O$2005,MES_REPORTE)) -> 7964.6018 | F22: =IF(PRODUCTOS!$A$14="","",SUMIFS(VENTAS!$L$6:$L$2005,VENTAS!$C$6:$C$2005,PRODUCTOS!$A$14,VENTAS!$O$6:$O$2005,MES_REPORTE)) -> 6947.0018 | H22: =IF(PRODUCTOS!$A$14="","",IFERROR(F22/SUM($F$14:$F$33),0)) -> 0.03134834 | I22: =IF(PRODUCTOS!$A$14="","",IFERROR(F22/E22,0)) -> 0.87223467
B23: =IF(PRODUCTOS!$A$15="","",PRODUCTOS!$B$15) | C23: =IF(PRODUCTOS!$A$15="","",SUMIFS(VENTAS!$E$6:$E$2005,VENTAS!$C$6:$C$2005,PRODUCTOS!$A$15,VENTAS!$O$6:$O$2005,MES_REPORTE)) | E23: =IF(PRODUCTOS!$A$15="","",SUMIFS(VENTAS!$J$6:$J$2005,VENTAS!$C$6:$C$2005,PRODUCTOS!$A$15,VENTAS!$O$6:$O$2005,MES_REPORTE)) | F23: =IF(PRODUCTOS!$A$15="","",SUMIFS(VENTAS!$L$6:$L$2005,VENTAS!$C$6:$C$2005,PRODUCTOS!$A$15,VENTAS!$O$6:$O$2005,MES_REPORTE)) | H23: =IF(PRODUCTOS!$A$15="","",IFERROR(F23/SUM($F$14:$F$33),0)) | I23: =IF(PRODUCTOS!$A$15="","",IFERROR(F23/E23,0))
B24: =IF(PRODUCTOS!$A$16="","",PRODUCTOS!$B$16) | C24: =IF(PRODUCTOS!$A$16="","",SUMIFS(VENTAS!$E$6:$E$2005,VENTAS!$C$6:$C$2005,PRODUCTOS!$A$16,VENTAS!$O$6:$O$2005,MES_REPORTE)) | E24: =IF(PRODUCTOS!$A$16="","",SUMIFS(VENTAS!$J$6:$J$2005,VENTAS!$C$6:$C$2005,PRODUCTOS!$A$16,VENTAS!$O$6:$O$2005,MES_REPORTE)) | F24: =IF(PRODUCTOS!$A$16="","",SUMIFS(VENTAS!$L$6:$L$2005,VENTAS!$C$6:$C$2005,PRODUCTOS!$A$16,VENTAS!$O$6:$O$2005,MES_REPORTE)) | H24: =IF(PRODUCTOS!$A$16="","",IFERROR(F24/SUM($F$14:$F$33),0)) | I24: =IF(PRODUCTOS!$A$16="","",IFERROR(F24/E24,0))
B25: =IF(PRODUCTOS!$A$17="","",PRODUCTOS!$B$17) | C25: =IF(PRODUCTOS!$A$17="","",SUMIFS(VENTAS!$E$6:$E$2005,VENTAS!$C$6:$C$2005,PRODUCTOS!$A$17,VENTAS!$O$6:$O$2005,MES_REPORTE)) | E25: =IF(PRODUCTOS!$A$17="","",SUMIFS(VENTAS!$J$6:$J$2005,VENTAS!$C$6:$C$2005,PRODUCTOS!$A$17,VENTAS!$O$6:$O$2005,MES_REPORTE)) | F25: =IF(PRODUCTOS!$A$17="","",SUMIFS(VENTAS!$L$6:$L$2005,VENTAS!$C$6:$C$2005,PRODUCTOS!$A$17,VENTAS!$O$6:$O$2005,MES_REPORTE)) | H25: =IF(PRODUCTOS!$A$17="","",IFERROR(F25/SUM($F$14:$F$33),0)) | I25: =IF(PRODUCTOS!$A$17="","",IFERROR(F25/E25,0))
B26: =IF(PRODUCTOS!$A$18="","",PRODUCTOS!$B$18) | C26: =IF(PRODUCTOS!$A$18="","",SUMIFS(VENTAS!$E$6:$E$2005,VENTAS!$C$6:$C$2005,PRODUCTOS!$A$18,VENTAS!$O$6:$O$2005,MES_REPORTE)) | E26: =IF(PRODUCTOS!$A$18="","",SUMIFS(VENTAS!$J$6:$J$2005,VENTAS!$C$6:$C$2005,PRODUCTOS!$A$18,VENTAS!$O$6:$O$2005,MES_REPORTE)) | F26: =IF(PRODUCTOS!$A$18="","",SUMIFS(VENTAS!$L$6:$L$2005,VENTAS!$C$6:$C$2005,PRODUCTOS!$A$18,VENTAS!$O$6:$O$2005,MES_REPORTE)) | H26: =IF(PRODUCTOS!$A$18="","",IFERROR(F26/SUM($F$14:$F$33),0)) | I26: =IF(PRODUCTOS!$A$18="","",IFERROR(F26/E26,0))
B27: =IF(PRODUCTOS!$A$19="","",PRODUCTOS!$B$19) | C27: =IF(PRODUCTOS!$A$19="","",SUMIFS(VENTAS!$E$6:$E$2005,VENTAS!$C$6:$C$2005,PRODUCTOS!$A$19,VENTAS!$O$6:$O$2005,MES_REPORTE)) | E27: =IF(PRODUCTOS!$A$19="","",SUMIFS(VENTAS!$J$6:$J$2005,VENTAS!$C$6:$C$2005,PRODUCTOS!$A$19,VENTAS!$O$6:$O$2005,MES_REPORTE)) | F27: =IF(PRODUCTOS!$A$19="","",SUMIFS(VENTAS!$L$6:$L$2005,VENTAS!$C$6:$C$2005,PRODUCTOS!$A$19,VENTAS!$O$6:$O$2005,MES_REPORTE)) | H27: =IF(PRODUCTOS!$A$19="","",IFERROR(F27/SUM($F$14:$F$33),0)) | I27: =IF(PRODUCTOS!$A$19="","",IFERROR(F27/E27,0))
B28: =IF(PRODUCTOS!$A$20="","",PRODUCTOS!$B$20) | C28: =IF(PRODUCTOS!$A$20="","",SUMIFS(VENTAS!$E$6:$E$2005,VENTAS!$C$6:$C$2005,PRODUCTOS!$A$20,VENTAS!$O$6:$O$2005,MES_REPORTE)) | E28: =IF(PRODUCTOS!$A$20="","",SUMIFS(VENTAS!$J$6:$J$2005,VENTAS!$C$6:$C$2005,PRODUCTOS!$A$20,VENTAS!$O$6:$O$2005,MES_REPORTE)) | F28: =IF(PRODUCTOS!$A$20="","",SUMIFS(VENTAS!$L$6:$L$2005,VENTAS!$C$6:$C$2005,PRODUCTOS!$A$20,VENTAS!$O$6:$O$2005,MES_REPORTE)) | H28: =IF(PRODUCTOS!$A$20="","",IFERROR(F28/SUM($F$14:$F$33),0)) | I28: =IF(PRODUCTOS!$A$20="","",IFERROR(F28/E28,0))
B29: =IF(PRODUCTOS!$A$21="","",PRODUCTOS!$B$21) | C29: =IF(PRODUCTOS!$A$21="","",SUMIFS(VENTAS!$E$6:$E$2005,VENTAS!$C$6:$C$2005,PRODUCTOS!$A$21,VENTAS!$O$6:$O$2005,MES_REPORTE)) | E29: =IF(PRODUCTOS!$A$21="","",SUMIFS(VENTAS!$J$6:$J$2005,VENTAS!$C$6:$C$2005,PRODUCTOS!$A$21,VENTAS!$O$6:$O$2005,MES_REPORTE)) | F29: =IF(PRODUCTOS!$A$21="","",SUMIFS(VENTAS!$L$6:$L$2005,VENTAS!$C$6:$C$2005,PRODUCTOS!$A$21,VENTAS!$O$6:$O$2005,MES_REPORTE)) | H29: =IF(PRODUCTOS!$A$21="","",IFERROR(F29/SUM($F$14:$F$33),0)) | I29: =IF(PRODUCTOS!$A$21="","",IFERROR(F29/E29,0))
B30: =IF(PRODUCTOS!$A$22="","",PRODUCTOS!$B$22) | C30: =IF(PRODUCTOS!$A$22="","",SUMIFS(VENTAS!$E$6:$E$2005,VENTAS!$C$6:$C$2005,PRODUCTOS!$A$22,VENTAS!$O$6:$O$2005,MES_REPORTE)) | E30: =IF(PRODUCTOS!$A$22="","",SUMIFS(VENTAS!$J$6:$J$2005,VENTAS!$C$6:$C$2005,PRODUCTOS!$A$22,VENTAS!$O$6:$O$2005,MES_REPORTE)) | F30: =IF(PRODUCTOS!$A$22="","",SUMIFS(VENTAS!$L$6:$L$2005,VENTAS!$C$6:$C$2005,PRODUCTOS!$A$22,VENTAS!$O$6:$O$2005,MES_REPORTE)) | H30: =IF(PRODUCTOS!$A$22="","",IFERROR(F30/SUM($F$14:$F$33),0)) | I30: =IF(PRODUCTOS!$A$22="","",IFERROR(F30/E30,0))
B31: =IF(PRODUCTOS!$A$23="","",PRODUCTOS!$B$23) | C31: =IF(PRODUCTOS!$A$23="","",SUMIFS(VENTAS!$E$6:$E$2005,VENTAS!$C$6:$C$2005,PRODUCTOS!$A$23,VENTAS!$O$6:$O$2005,MES_REPORTE)) | E31: =IF(PRODUCTOS!$A$23="","",SUMIFS(VENTAS!$J$6:$J$2005,VENTAS!$C$6:$C$2005,PRODUCTOS!$A$23,VENTAS!$O$6:$O$2005,MES_REPORTE)) | F31: =IF(PRODUCTOS!$A$23="","",SUMIFS(VENTAS!$L$6:$L$2005,VENTAS!$C$6:$C$2005,PRODUCTOS!$A$23,VENTAS!$O$6:$O$2005,MES_REPORTE)) | H31: =IF(PRODUCTOS!$A$23="","",IFERROR(F31/SUM($F$14:$F$33),0)) | I31: =IF(PRODUCTOS!$A$23="","",IFERROR(F31/E31,0))
B32: =IF(PRODUCTOS!$A$24="","",PRODUCTOS!$B$24) | C32: =IF(PRODUCTOS!$A$24="","",SUMIFS(VENTAS!$E$6:$E$2005,VENTAS!$C$6:$C$2005,PRODUCTOS!$A$24,VENTAS!$O$6:$O$2005,MES_REPORTE)) | E32: =IF(PRODUCTOS!$A$24="","",SUMIFS(VENTAS!$J$6:$J$2005,VENTAS!$C$6:$C$2005,PRODUCTOS!$A$24,VENTAS!$O$6:$O$2005,MES_REPORTE)) | F32: =IF(PRODUCTOS!$A$24="","",SUMIFS(VENTAS!$L$6:$L$2005,VENTAS!$C$6:$C$2005,PRODUCTOS!$A$24,VENTAS!$O$6:$O$2005,MES_REPORTE)) | H32: =IF(PRODUCTOS!$A$24="","",IFERROR(F32/SUM($F$14:$F$33),0)) | I32: =IF(PRODUCTOS!$A$24="","",IFERROR(F32/E32,0))
B33: =IF(PRODUCTOS!$A$25="","",PRODUCTOS!$B$25) | C33: =IF(PRODUCTOS!$A$25="","",SUMIFS(VENTAS!$E$6:$E$2005,VENTAS!$C$6:$C$2005,PRODUCTOS!$A$25,VENTAS!$O$6:$O$2005,MES_REPORTE)) | E33: =IF(PRODUCTOS!$A$25="","",SUMIFS(VENTAS!$J$6:$J$2005,VENTAS!$C$6:$C$2005,PRODUCTOS!$A$25,VENTAS!$O$6:$O$2005,MES_REPORTE)) | F33: =IF(PRODUCTOS!$A$25="","",SUMIFS(VENTAS!$L$6:$L$2005,VENTAS!$C$6:$C$2005,PRODUCTOS!$A$25,VENTAS!$O$6:$O$2005,MES_REPORTE)) | H33: =IF(PRODUCTOS!$A$25="","",IFERROR(F33/SUM($F$14:$F$33),0)) | I33: =IF(PRODUCTOS!$A$25="","",IFERROR(F33/E33,0))
B35: Insumos por reordenar (desde INSUMOS)
B36: Insumo | C36: Stock actual | E36: Proveedor | F36: Sugerido comprar (presentaciones) | H36: Estado
B37: =IFERROR(INDEX(INSUMOS!$B:$B,SMALL(INSUMOS!$AA$6:$AA$205,1)),"") -> Granola | C37: =IFERROR(INDEX(INSUMOS!$T:$T,SMALL(INSUMOS!$AA$6:$AA$205,1)),"") -> 400 | E37: =IFERROR(INDEX(INSUMOS!$J:$J,SMALL(INSUMOS!$AA$6:$AA$205,1)),"") -> Mayorista | F37: =IFERROR(INDEX(INSUMOS!$Z:$Z,SMALL(INSUMOS!$AA$6:$AA$205,1)),"") -> 1 | H37: =IFERROR(INDEX(INSUMOS!$Y:$Y,SMALL(INSUMOS!$AA$6:$AA$205,1)),"") -> REORDENAR
B38: =IFERROR(INDEX(INSUMOS!$B:$B,SMALL(INSUMOS!$AA$6:$AA$205,2)),"") | C38: =IFERROR(INDEX(INSUMOS!$T:$T,SMALL(INSUMOS!$AA$6:$AA$205,2)),"") | E38: =IFERROR(INDEX(INSUMOS!$J:$J,SMALL(INSUMOS!$AA$6:$AA$205,2)),"") | F38: =IFERROR(INDEX(INSUMOS!$Z:$Z,SMALL(INSUMOS!$AA$6:$AA$205,2)),"") | H38: =IFERROR(INDEX(INSUMOS!$Y:$Y,SMALL(INSUMOS!$AA$6:$AA$205,2)),"")
B39: =IFERROR(INDEX(INSUMOS!$B:$B,SMALL(INSUMOS!$AA$6:$AA$205,3)),"") | C39: =IFERROR(INDEX(INSUMOS!$T:$T,SMALL(INSUMOS!$AA$6:$AA$205,3)),"") | E39: =IFERROR(INDEX(INSUMOS!$J:$J,SMALL(INSUMOS!$AA$6:$AA$205,3)),"") | F39: =IFERROR(INDEX(INSUMOS!$Z:$Z,SMALL(INSUMOS!$AA$6:$AA$205,3)),"") | H39: =IFERROR(INDEX(INSUMOS!$Y:$Y,SMALL(INSUMOS!$AA$6:$AA$205,3)),"")
B40: =IFERROR(INDEX(INSUMOS!$B:$B,SMALL(INSUMOS!$AA$6:$AA$205,4)),"") | C40: =IFERROR(INDEX(INSUMOS!$T:$T,SMALL(INSUMOS!$AA$6:$AA$205,4)),"") | E40: =IFERROR(INDEX(INSUMOS!$J:$J,SMALL(INSUMOS!$AA$6:$AA$205,4)),"") | F40: =IFERROR(INDEX(INSUMOS!$Z:$Z,SMALL(INSUMOS!$AA$6:$AA$205,4)),"") | H40: =IFERROR(INDEX(INSUMOS!$Y:$Y,SMALL(INSUMOS!$AA$6:$AA$205,4)),"")
B41: =IFERROR(INDEX(INSUMOS!$B:$B,SMALL(INSUMOS!$AA$6:$AA$205,5)),"") | C41: =IFERROR(INDEX(INSUMOS!$T:$T,SMALL(INSUMOS!$AA$6:$AA$205,5)),"") | E41: =IFERROR(INDEX(INSUMOS!$J:$J,SMALL(INSUMOS!$AA$6:$AA$205,5)),"") | F41: =IFERROR(INDEX(INSUMOS!$Z:$Z,SMALL(INSUMOS!$AA$6:$AA$205,5)),"") | H41: =IFERROR(INDEX(INSUMOS!$Y:$Y,SMALL(INSUMOS!$AA$6:$AA$205,5)),"")
B42: =IFERROR(INDEX(INSUMOS!$B:$B,SMALL(INSUMOS!$AA$6:$AA$205,6)),"") | C42: =IFERROR(INDEX(INSUMOS!$T:$T,SMALL(INSUMOS!$AA$6:$AA$205,6)),"") | E42: =IFERROR(INDEX(INSUMOS!$J:$J,SMALL(INSUMOS!$AA$6:$AA$205,6)),"") | F42: =IFERROR(INDEX(INSUMOS!$Z:$Z,SMALL(INSUMOS!$AA$6:$AA$205,6)),"") | H42: =IFERROR(INDEX(INSUMOS!$Y:$Y,SMALL(INSUMOS!$AA$6:$AA$205,6)),"")
B43: =IFERROR(INDEX(INSUMOS!$B:$B,SMALL(INSUMOS!$AA$6:$AA$205,7)),"") | C43: =IFERROR(INDEX(INSUMOS!$T:$T,SMALL(INSUMOS!$AA$6:$AA$205,7)),"") | E43: =IFERROR(INDEX(INSUMOS!$J:$J,SMALL(INSUMOS!$AA$6:$AA$205,7)),"") | F43: =IFERROR(INDEX(INSUMOS!$Z:$Z,SMALL(INSUMOS!$AA$6:$AA$205,7)),"") | H43: =IFERROR(INDEX(INSUMOS!$Y:$Y,SMALL(INSUMOS!$AA$6:$AA$205,7)),"")
...

Sheet INSUMOS
A1: INSUMOS E INVENTARIO
A2: Catálogo de materias primas y empaques. Todas las cantidades en UNIDAD BASE (g, ml o u). Stock actual = inicial + compras − consumo por ventas (recetas) ± mermas/ajustes.
A3: Costo vigente = último costo de COMPRAS (si existe) o el precio de catálogo. Costo real = costo ÷ % aprovechamiento (cáscara, hojas, residuos).
T4: Valor total inventario: | U4: =SUM(U6:U205) -> 388439.3 | W4: Faltantes ₡: | X4: =SUM(X6:X205) -> 0
A5: Código | B5: Insumo | C5: Categoría | D5: Unidad base | E5: Presentación de compra | F5: Contenido por presentación (unid. base) | G5: Precio presentación sin IVA (catálogo) | H5: % IVA en compra | I5: % aprovecha-miento | J5: Proveedor principal | K5: Stock mínimo (unid. base) | L5: Stock inicial (unid. base) | M5: Costo catálogo por unid. base | N5: Último costo de compra por unid. base | O5: Costo vigente por unid. base | P5: Costo REAL por unid. base (con aprovech.) | Q5: Entradas (compras) | R5: Consumo por ventas (recetas) | S5: Mermas y ajustes (±) | T5: STOCK TEÓRICO ACTUAL | U5: Valor del inventario | V5: Conteo físico (unid. base) | W5: Diferencia (físico − teórico) | X5: Valor de la diferencia | Y5: Estado | Z5: Sugerido a comprar (presentaciones) | AA5: aux alerta
A6: I001 | B6: Fresas frescas | C6: Fruta | D6: g | E6: Caja 5 kg | F6: 5000 | G6: 14000 | H6: 0.01 | I6: 0.85 | J6: Productor / feria | K6: 5000 | L6: 12000 | M6: =IF($A6="","",IFERROR($G6/$F6,0)) -> 2.8 | N6: =IF($A6="","",IFERROR(SUMIFS(COMPRAS!$N$6:$N$1005,COMPRAS!$D$6:$D$1005,$A6,COMPRAS!$R$6:$R$1005,1)/COUNTIFS(COMPRAS!$D$6:$D$1005,$A6,COMPRAS!$R$6:$R$1005,1),0)) -> 2.8 | O6: =IF($A6="","",IF($N6>0,$N6,$M6)) -> 2.8 | P6: =IF($A6="","",IF(N($I6)>0,$O6/$I6,$O6)) -> 3.2941176 | Q6: =IF($A6="","",SUMIFS(COMPRAS!$I$6:$I$1005,COMPRAS!$D$6:$D$1005,$A6)) -> 15000 | R6: =IF($A6="","",SUMIFS(RECETAS!$L$6:$L$605,RECETAS!$C$6:$C$605,$A6)) -> 17258.824 | S6: =IF($A6="","",SUMIFS(MERMAS!$J$6:$J$505,MERMAS!$B$6:$B$505,$A6)) -> -600 | T6: =IF($A6="","",N($L6)+$Q6-$R6+$S6) -> 9141.1765 | U6: =IF($A6="","",$T6*$O6) -> 25595.294 | W6: =IF(OR($A6="",$V6=""),"",$V6-$T6) | X6: =IF($W6="","",$W6*$O6) | Y6: =IF($A6="","",IF($T6<=0,"AGOTADO",IF($T6<=N($K6),"REORDENAR","OK"))) -> OK | Z6: =IF($A6="","",IF($T6<=N($K6),ROUNDUP((2*N($K6)-$T6)/$F6,0),0)) -> 0 | AA6: =IF(OR($Y6="REORDENAR",$Y6="AGOTADO"),ROW(),"")
A7: I002 | B7: Mango maduro | C7: Fruta | D7: g | E7: Kilo | F7: 1000 | G7: 1200 | H7: 0.01 | I7: 0.65 | J7: Productor / feria | K7: 2000 | L7: 5000 | M7: =IF($A7="","",IFERROR($G7/$F7,0)) -> 1.2 | N7: =IF($A7="","",IFERROR(SUMIFS(COMPRAS!$N$6:$N$1005,COMPRAS!$D$6:$D$1005,$A7,COMPRAS!$R$6:$R$1005,1)/COUNTIFS(COMPRAS!$D$6:$D$1005,$A7,COMPRAS!$R$6:$R$1005,1),0)) -> 1.3 | O7: =IF($A7="","",IF($N7>0,$N7,$M7)) -> 1.3 | P7: =IF($A7="","",IF(N($I7)>0,$O7/$I7,$O7)) -> 2 | Q7: =IF($A7="","",SUMIFS(COMPRAS!$I$6:$I$1005,COMPRAS!$D$6:$D$1005,$A7)) -> 5000 | R7: =IF($A7="","",SUMIFS(RECETAS!$L$6:$L$605,RECETAS!$C$6:$C$605,$A7)) -> 3600 | S7: =IF($A7="","",SUMIFS(MERMAS!$J$6:$J$505,MERMAS!$B$6:$B$505,$A7)) -> 0 | T7: =IF($A7="","",N($L7)+$Q7-$R7+$S7) -> 6400 | U7: =IF($A7="","",$T7*$O7) -> 8320 | W7: =IF(OR($A7="",$V7=""),"",$V7-$T7) | X7: =IF($W7="","",$W7*$O7) | Y7: =IF($A7="","",IF($T7<=0,"AGOTADO",IF($T7<=N($K7),"REORDENAR","OK"))) -> OK | Z7: =IF($A7="","",IF($T7<=N($K7),ROUNDUP((2*N($K7)-$T7)/$F7,0),0)) -> 0 | AA7: =IF(OR($Y7="REORDENAR",$Y7="AGOTADO"),ROW(),"")
A8: I003 | B8: Pulpa de maracuyá | C8: Fruta | D8: g | E8: Bolsa 1 kg | F8: 1000 | G8: 2800 | H8: 0.01 | I8: 1 | J8: Distribuidora | K8: 1000 | L8: 3000 | M8: =IF($A8="","",IFERROR($G8/$F8,0)) -> 2.8 | N8: =IF($A8="","",IFERROR(SUMIFS(COMPRAS!$N$6:$N$1005,COMPRAS!$D$6:$D$1005,$A8,COMPRAS!$R$6:$R$1005,1)/COUNTIFS(COMPRAS!$D$6:$D$1005,$A8,COMPRAS!$R$6:$R$1005,1),0)) -> 0 | O8: =IF($A8="","",IF($N8>0,$N8,$M8)) -> 2.8 | P8: =IF($A8="","",IF(N($I8)>0,$O8/$I8,$O8)) -> 2.8 | Q8: =IF($A8="","",SUMIFS(COMPRAS!$I$6:$I$1005,COMPRAS!$D$6:$D$1005,$A8)) -> 0 | R8: =IF($A8="","",SUMIFS(RECETAS!$L$6:$L$605,RECETAS!$C$6:$C$605,$A8)) -> 780 | S8: =IF($A8="","",SUMIFS(MERMAS!$J$6:$J$505,MERMAS!$B$6:$B$505,$A8)) -> 0 | T8: =IF($A8="","",N($L8)+$Q8-$R8+$S8) -> 2220 | U8: =IF($A8="","",$T8*$O8) -> 6216 | W8: =IF(OR($A8="",$V8=""),"",$V8-$T8) | X8: =IF($W8="","",$W8*$O8) | Y8: =IF($A8="","",IF($T8<=0,"AGOTADO",IF($T8<=N($K8),"REORDENAR","OK"))) -> OK | Z8: =IF($A8="","",IF($T8<=N($K8),ROUNDUP((2*N($K8)-$T8)/$F8,0),0)) -> 0 | AA8: =IF(OR($Y8="REORDENAR",$Y8="AGOTADO"),ROW(),"")
A9: I004 | B9: Crema dulce | C9: Lácteos | D9: ml | E9: Caja 1 L | F9: 1000 | G9: 2500 | H9: 0.01 | I9: 1 | J9: Distribuidora lácteos | K9: 4000 | L9: 10000 | M9: =IF($A9="","",IFERROR($G9/$F9,0)) -> 2.5 | N9: =IF($A9="","",IFERROR(SUMIFS(COMPRAS!$N$6:$N$1005,COMPRAS!$D$6:$D$1005,$A9,COMPRAS!$R$6:$R$1005,1)/COUNTIFS(COMPRAS!$D$6:$D$1005,$A9,COMPRAS!$R$6:$R$1005,1),0)) -> 2.55 | O9: =IF($A9="","",IF($N9>0,$N9,$M9)) -> 2.55 | P9: =IF($A9="","",IF(N($I9)>0,$O9/$I9,$O9)) -> 2.55 | Q9: =IF($A9="","",SUMIFS(COMPRAS!$I$6:$I$1005,COMPRAS!$D$6:$D$1005,$A9)) -> 12000 | R9: =IF($A9="","",SUMIFS(RECETAS!$L$6:$L$605,RECETAS!$C$6:$C$605,$A9)) -> 7645 | S9: =IF($A9="","",SUMIFS(MERMAS!$J$6:$J$505,MERMAS!$B$6:$B$505,$A9)) -> -500 | T9: =IF($A9="","",N($L9)+$Q9-$R9+$S9) -> 13855 | U9: =IF($A9="","",$T9*$O9) -> 35330.25 | W9: =IF(OR($A9="",$V9=""),"",$V9-$T9) | X9: =IF($W9="","",$W9*$O9) | Y9: =IF($A9="","",IF($T9<=0,"AGOTADO",IF($T9<=N($K9),"REORDENAR","OK"))) -> OK | Z9: =IF($A9="","",IF($T9<=N($K9),ROUNDUP((2*N($K9)-$T9)/$F9,0),0)) -> 0 | AA9: =IF(OR($Y9="REORDENAR",$Y9="AGOTADO"),ROW(),"")
A10: I005 | B10: Leche condensada | C10: Lácteos | D10: g | E10: Lata 397 g | F10: 397 | G10: 1250 | H10: 0.13 | I10: 0.97 | J10: Mayorista | K10: 3970 | L10: 7940 | M10: =IF($A10="","",IFERROR($G10/$F10,0)) -> 3.1486146 | N10: =IF($A10="","",IFERROR(SUMIFS(COMPRAS!$N$6:$N$1005,COMPRAS!$D$6:$D$1005,$A10,COMPRAS!$R$6:$R$1005,1)/COUNTIFS(COMPRAS!$D$6:$D$1005,$A10,COMPRAS!$R$6:$R$1005,1),0)) -> 3.1486146 | O10: =IF($A10="","",IF($N10>0,$N10,$M10)) -> 3.1486146 | P10: =IF($A10="","",IF(N($I10)>0,$O10/$I10,$O10)) -> 3.2459944 | Q10: =IF($A10="","",SUMIFS(COMPRAS!$I$6:$I$1005,COMPRAS!$D$6:$D$1005,$A10)) -> 9528 | R10: =IF($A10="","",SUMIFS(RECETAS!$L$6:$L$605,RECETAS!$C$6:$C$605,$A10)) -> 3592.7835 | S10: =IF($A10="","",SUMIFS(MERMAS!$J$6:$J$505,MERMAS!$B$6:$B$505,$A10)) -> 0 | T10: =IF($A10="","",N($L10)+$Q10-$R10+$S10) -> 13875.216 | U10: =IF($A10="","",$T10*$O10) -> 43687.709 | W10: =IF(OR($A10="",$V10=""),"",$V10-$T10) | X10: =IF($W10="","",$W10*$O10) | Y10: =IF($A10="","",IF($T10<=0,"AGOTADO",IF($T10<=N($K10),"REORDENAR","OK"))) -> OK | Z10: =IF($A10="","",IF($T10<=N($K10),ROUNDUP((2*N($K10)-$T10)/$F10,0),0)) -> 0 | AA10: =IF(OR($Y10="REORDENAR",$Y10="AGOTADO"),ROW(),"")
A11: I006 | B11: Esencia de vainilla | C11: Abarrotes | D11: ml | E11: Frasco 250 ml | F11: 250 | G11: 1800 | H11: 0.13 | I11: 1 | J11: Mayorista | K11: 250 | L11: 500 | M11: =IF($A11="","",IFERROR($G11/$F11,0)) -> 7.2 | N11: =IF($A11="","",IFERROR(SUMIFS(COMPRAS!$N$6:$N$1005,COMPRAS!$D$6:$D$1005,$A11,COMPRAS!$R$6:$R$1005,1)/COUNTIFS(COMPRAS!$D$6:$D$1005,$A11,COMPRAS!$R$6:$R$1005,1),0)) -> 0 | O11: =IF($A11="","",IF($N11>0,$N11,$M11)) -> 7.2 | P11: =IF($A11="","",IF(N($I11)>0,$O11/$I11,$O11)) -> 7.2 | Q11: =IF($A11="","",SUMIFS(COMPRAS!$I$6:$I$1005,COMPRAS!$D$6:$D$1005,$A11)) -> 0 | R11: =IF($A11="","",SUMIFS(RECETAS!$L$6:$L$605,RECETAS!$C$6:$C$605,$A11)) -> 151 | S11: =IF($A11="","",SUMIFS(MERMAS!$J$6:$J$505,MERMAS!$B$6:$B$505,$A11)) -> 0 | T11: =IF($A11="","",N($L11)+$Q11-$R11+$S11) -> 349 | U11: =IF($A11="","",$T11*$O11) -> 2512.8 | W11: =IF(OR($A11="",$V11=""),"",$V11-$T11) | X11: =IF($W11="","",$W11*$O11) | Y11: =IF($A11="","",IF($T11<=0,"AGOTADO",IF($T11<=N($K11),"REORDENAR","OK"))) -> OK | Z11: =IF($A11="","",IF($T11<=N($K11),ROUNDUP((2*N($K11)-$T11)/$F11,0),0)) -> 0 | AA11: =IF(OR($Y11="REORDENAR",$Y11="AGOTADO"),ROW(),"")
A12: I007 | B12: Azúcar | C12: Abarrotes | D12: g | E12: Bolsa 2 kg | F12: 2000 | G12: 1700 | H12: 0.01 | I12: 1 | J12: Mayorista | K12: 2000 | L12: 4000 | M12: =IF($A12="","",IFERROR($G12/$F12,0)) -> 0.85 | N12: =IF($A12="","",IFERROR(SUMIFS(COMPRAS!$N$6:$N$1005,COMPRAS!$D$6:$D$1005,$A12,COMPRAS!$R$6:$R$1005,1)/COUNTIFS(COMPRAS!$D$6:$D$1005,$A12,COMPRAS!$R$6:$R$1005,1),0)) -> 0 | O12: =IF($A12="","",IF($N12>0,$N12,$M12)) -> 0.85 | P12: =IF($A12="","",IF(N($I12)>0,$O12/$I12,$O12)) -> 0.85 | Q12: =IF($A12="","",SUMIFS(COMPRAS!$I$6:$I$1005,COMPRAS!$D$6:$D$1005,$A12)) -> 0 | R12: =IF($A12="","",SUMIFS(RECETAS!$L$6:$L$605,RECETAS!$C$6:$C$605,$A12)) -> 120 | S12: =IF($A12="","",SUMIFS(MERMAS!$J$6:$J$505,MERMAS!$B$6:$B$505,$A12)) -> 0 | T12: =IF($A12="","",N($L12)+$Q12-$R12+$S12) -> 3880 | U12: =IF($A12="","",$T12*$O12) -> 3298 | W12: =IF(OR($A12="",$V12=""),"",$V12-$T12) | X12: =IF($W12="","",$W12*$O12) | Y12: =IF($A12="","",IF($T12<=0,"AGOTADO",IF($T12<=N($K12),"REORDENAR","OK"))) -> OK | Z12: =IF($A12="","",IF($T12<=N($K12),ROUNDUP((2*N($K12)-$T12)/$F12,0),0)) -> 0 | AA12: =IF(OR($Y12="REORDENAR",$Y12="AGOTADO"),ROW(),"")
A13: I008 | B13: Galleta Oreo triturada | C13: Toppings | D13: g | E13: Paquete 432 g | F13: 432 | G13: 2600 | H13: 0.13 | I13: 0.95 | J13: Mayorista | K13: 864 | L13: 2160 | M13: =IF($A13="","",IFERROR($G13/$F13,0)) -> 6.0185185 | N13: =IF($A13="","",IFERROR(SUMIFS(COMPRAS!$N$6:$N$1005,COMPRAS!$D$6:$D$1005,$A13,COMPRAS!$R$6:$R$1005,1)/COUNTIFS(COMPRAS!$D$6:$D$1005,$A13,COMPRAS!$R$6:$R$1005,1),0)) -> 6.0185185 | O13: =IF($A13="","",IF($N13>0,$N13,$M13)) -> 6.0185185 | P13: =IF($A13="","",IF(N($I13)>0,$O13/$I13,$O13)) -> 6.3352827 | Q13: =IF($A13="","",SUMIFS(COMPRAS!$I$6:$I$1005,COMPRAS!$D$6:$D$1005,$A13)) -> 1728 | R13: =IF($A13="","",SUMIFS(RECETAS!$L$6:$L$605,RECETAS!$C$6:$C$605,$A13)) -> 1789.4737 | S13: =IF($A13="","",SUMIFS(MERMAS!$J$6:$J$505,MERMAS!$B$6:$B$505,$A13)) -> 0 | T13: =IF($A13="","",N($L13)+$Q13-$R13+$S13) -> 2098.5263 | U13: =IF($A13="","",$T13*$O13) -> 12630.019 | W13: =IF(OR($A13="",$V13=""),"",$V13-$T13) | X13: =IF($W13="","",$W13*$O13) | Y13: =IF($A13="","",IF($T13<=0,"AGOTADO",IF($T13<=N($K13),"REORDENAR","OK"))) -> OK | Z13: =IF($A13="","",IF($T13<=N($K13),ROUNDUP((2*N($K13)-$T13)/$F13,0),0)) -> 0 | AA13: =IF(OR($Y13="REORDENAR",$Y13="AGOTADO"),ROW(),"")
A14: I009 | B14: Brownie (topping) | C14: Toppings | D14: g | E14: Bandeja 1 kg | F14: 1000 | G14: 5500 | H14: 0.13 | I14: 0.95 | J14: Panadería | K14: 500 | L14: 1000 | M14: =IF($A14="","",IFERROR($G14/$F14,0)) -> 5.5 | N14: =IF($A14="","",IFERROR(SUMIFS(COMPRAS!$N$6:$N$1005,COMPRAS!$D$6:$D$1005,$A14,COMPRAS!$R$6:$R$1005,1)/COUNTIFS(COMPRAS!$D$6:$D$1005,$A14,COMPRAS!$R$6:$R$1005,1),0)) -> 0 | O14: =IF($A14="","",IF($N14>0,$N14,$M14)) -> 5.5 | P14: =IF($A14="","",IF(N($I14)>0,$O14/$I14,$O14)) -> 5.7894737 | Q14: =IF($A14="","",SUMIFS(COMPRAS!$I$6:$I$1005,COMPRAS!$D$6:$D$1005,$A14)) -> 0 | R14: =IF($A14="","",SUMIFS(RECETAS!$L$6:$L$605,RECETAS!$C$6:$C$605,$A14)) -> 221.05263 | S14: =IF($A14="","",SUMIFS(MERMAS!$J$6:$J$505,MERMAS!$B$6:$B$505,$A14)) -> 0 | T14: =IF($A14="","",N($L14)+$Q14-$R14+$S14) -> 778.94737 | U14: =IF($A14="","",$T14*$O14) -> 4284.2105 | W14: =IF(OR($A14="",$V14=""),"",$V14-$T14) | X14: =IF($W14="","",$W14*$O14) | Y14: =IF($A14="","",IF($T14<=0,"AGOTADO",IF($T14<=N($K14),"REORDENAR","OK"))) -> OK | Z14: =IF($A14="","",IF($T14<=N($K14),ROUNDUP((2*N($K14)-$T14)/$F14,0),0)) -> 0 | AA14: =IF(OR($Y14="REORDENAR",$Y14="AGOTADO"),ROW(),"")
A15: I010 | B15: Marshmallows | C15: Toppings | D15: g | E15: Bolsa 500 g | F15: 500 | G15: 2200 | H15: 0.13 | I15: 1 | J15: Mayorista | K15: 500 | L15: 1000 | M15: =IF($A15="","",IFERROR($G15/$F15,0)) -> 4.4 | N15: =IF($A15="","",IFERROR(SUMIFS(COMPRAS!$N$6:$N$1005,COMPRAS!$D$6:$D$1005,$A15,COMPRAS!$R$6:$R$1005,1)/COUNTIFS(COMPRAS!$D$6:$D$1005,$A15,COMPRAS!$R$6:$R$1005,1),0)) -> 0 | O15: =IF($A15="","",IF($N15>0,$N15,$M15)) -> 4.4 | P15: =IF($A15="","",IF(N($I15)>0,$O15/$I15,$O15)) -> 4.4 | Q15: =IF($A15="","",SUMIFS(COMPRAS!$I$6:$I$1005,COMPRAS!$D$6:$D$1005,$A15)) -> 0 | R15: =IF($A15="","",SUMIFS(RECETAS!$L$6:$L$605,RECETAS!$C$6:$C$605,$A15)) -> 440 | S15: =IF($A15="","",SUMIFS(MERMAS!$J$6:$J$505,MERMAS!$B$6:$B$505,$A15)) -> 0 | T15: =IF($A15="","",N($L15)+$Q15-$R15+$S15) -> 560 | U15: =IF($A15="","",$T15*$O15) -> 2464 | W15: =IF(OR($A15="",$V15=""),"",$V15-$T15) | X15: =IF($W15="","",$W15*$O15) | Y15: =IF($A15="","",IF($T15<=0,"AGOTADO",IF($T15<=N($K15),"REORDENAR","OK"))) -> OK | Z15: =IF($A15="","",IF($T15<=N($K15),ROUNDUP((2*N($K15)-$T15)/$F15,0),0)) -> 0 | AA15: =IF(OR($Y15="REORDENAR",$Y15="AGOTADO"),ROW(),"")
A16: I011 | B16: Gomitas | C16: Toppings | D16: g | E16: Bolsa 1 kg | F16: 1000 | G16: 3800 | H16: 0.13 | I16: 1 | J16: Mayorista | K16: 500 | L16: 1000 | M16: =IF($A16="","",IFERROR($G16/$F16,0)) -> 3.8 | N16: =IF($A16="","",IFERROR(SUMIFS(COMPRAS!$N$6:$N$1005,COMPRAS!$D$6:$D$1005,$A16,COMPRAS!$R$6:$R$1005,1)/COUNTIFS(COMPRAS!$D$6:$D$1005,$A16,COMPRAS!$R$6:$R$1005,1),0)) -> 0 | O16: =IF($A16="","",IF($N16>0,$N16,$M16)) -> 3.8 | P16: =IF($A16="","",IF(N($I16)>0,$O16/$I16,$O16)) -> 3.8 | Q16: =IF($A16="","",SUMIFS(COMPRAS!$I$6:$I$1005,COMPRAS!$D$6:$D$1005,$A16)) -> 0 | R16: =IF($A16="","",SUMIFS(RECETAS!$L$6:$L$605,RECETAS!$C$6:$C$605,$A16)) -> 440 | S16: =IF($A16="","",SUMIFS(MERMAS!$J$6:$J$505,MERMAS!$B$6:$B$505,$A16)) -> 0 | T16: =IF($A16="","",N($L16)+$Q16-$R16+$S16) -> 560 | U16: =IF($A16="","",$T16*$O16) -> 2128 | W16: =IF(OR($A16="",$V16=""),"",$V16-$T16) | X16: =IF($W16="","",$W16*$O16) | Y16: =IF($A16="","",IF($T16<=0,"AGOTADO",IF($T16<=N($K16),"REORDENAR","OK"))) -> OK | Z16: =IF($A16="","",IF($T16<=N($K16),ROUNDUP((2*N($K16)-$T16)/$F16,0),0)) -> 0 | AA16: =IF(OR($Y16="REORDENAR",$Y16="AGOTADO"),ROW(),"")
A17: I012 | B17: Granola | C17: Toppings | D17: g | E17: Bolsa 1 kg | F17: 1000 | G17: 4200 | H17: 0.13 | I17: 1 | J17: Mayorista | K17: 500 | L17: 1000 | M17: =IF($A17="","",IFERROR($G17/$F17,0)) -> 4.2 | N17: =IF($A17="","",IFERROR(SUMIFS(COMPRAS!$N$6:$N$1005,COMPRAS!$D$6:$D$1005,$A17,COMPRAS!$R$6:$R$1005,1)/COUNTIFS(COMPRAS!$D$6:$D$1005,$A17,COMPRAS!$R$6:$R$1005,1),0)) -> 0 | O17: =IF($A17="","",IF($N17>0,$N17,$M17)) -> 4.2 | P17: =IF($A17="","",IF(N($I17)>0,$O17/$I17,$O17)) -> 4.2 | Q17: =IF($A17="","",SUMIFS(COMPRAS!$I$6:$I$1005,COMPRAS!$D$6:$D$1005,$A17)) -> 0 | R17: =IF($A17="","",SUMIFS(RECETAS!$L$6:$L$605,RECETAS!$C$6:$C$605,$A17)) -> 600 | S17: =IF($A17="","",SUMIFS(MERMAS!$J$6:$J$505,MERMAS!$B$6:$B$505,$A17)) -> 0 | T17: =IF($A17="","",N($L17)+$Q17-$R17+$S17) -> 400 | U17: =IF($A17="","",$T17*$O17) -> 1680 | W17: =IF(OR($A17="",$V17=""),"",$V17-$T17) | X17: =IF($W17="","",$W17*$O17) | Y17: =IF($A17="","",IF($T17<=0,"AGOTADO",IF($T17<=N($K17),"REORDENAR","OK"))) -> REORDENAR | Z17: =IF($A17="","",IF($T17<=N($K17),ROUNDUP((2*N($K17)-$T17)/$F17,0),0)) -> 1 | AA17: =IF(OR($Y17="REORDENAR",$Y17="AGOTADO"),ROW(),"") -> 17
... A36: I031 | B36: Huevos | C36: Abarrotes | D36: u | E36: Cartón 30 u | F36: 30 | G36: 3000 | H36: 0.01 | I36: 1 | J36: Granja | K36: 30 | L36: 60 | M36: =IF($A36="","",IFERROR($G36/$F36,0)) -> 100 | N36: =IF($A36="","",IFERROR(SUMIFS(COMPRAS!$N$6:$N$1005,COMPRAS!$D$6:$D$1005,$A36,COMPRAS!$R$6:$R$1005,1)/COUNTIFS(COMPRAS!$D$6:$D$1005,$A36,COMPRAS!$R$6:$R$1005,1),0)) -> 0 | O36: =IF($A36="","",IF($N36>0,$N36,$M36)) -> 100 | P36: =IF($A36="","",IF(N($I36)>0,$O36/$I36,$O36)) -> 100 | Q36: =IF($A36="","",SUMIFS(COMPRAS!$I$6:$I$1005,COMPRAS!$D$6:$D$1005,$A36)) -> 0 | R36: =IF($A36="","",SUMIFS(RECETAS!$L$6:$L$605,RECETAS!$C$6:$C$605,$A36)) -> 1.8 | S36: =IF($A36="","",SUMIFS(MERMAS!$J$6:$J$505,MERMAS!$B$6:$B$505,$A36)) -> 0 | T36: =IF($A36="","",N($L36)+$Q36-$R36+$S36) -> 58.2 | U36: =IF($A36="","",$T36*$O36) -> 5820 | W36: =IF(OR($A36="",$V36=""),"",$V36-$T36) | X36: =IF($W36="","",$W36*$O36) | Y36: =IF($A36="","",IF($T36<=0,"AGOTADO",IF($T36<=N($K36),"REORDENAR","OK"))) -> OK | Z36: =IF($A36="","",IF($T36<=N($K36),ROUNDUP((2*N($K36)-$T36)/$F36,0),0)) -> 0 | AA36: =IF(OR($Y36="REORDENAR",$Y36="AGOTADO"),ROW(),"")
M37: =IF($A37="","",IFERROR($G37/$F37,0)) | N37: =IF($A37="","",IFERROR(SUMIFS(COMPRAS!$N$6:$N$1005,COMPRAS!$D$6:$D$1005,$A37,COMPRAS!$R$6:$R$1005,1)/COUNTIFS(COMPRAS!$D$6:$D$1005,$A37,COMPRAS!$R$6:$R$1005,1),0)) | O37: =IF($A37="","",IF($N37>0,$N37,$M37)) | P37: =IF($A37="","",IF(N($I37)>0,$O37/$I37,$O37)) | Q37: =IF($A37="","",SUMIFS(COMPRAS!$I$6:$I$1005,COMPRAS!$D$6:$D$1005,$A37)) | R37: =IF($A37="","",SUMIFS(RECETAS!$L$6:$L$605,RECETAS!$C$6:$C$605,$A37)) | S37: =IF($A37="","",SUMIFS(MERMAS!$J$6:$J$505,MERMAS!$B$6:$B$505,$A37)) | T37: =IF($A37="","",N($L37)+$Q37-$R37+$S37) | U37: =IF($A37="","",$T37*$O37) | W37: =IF(OR($A37="",$V37=""),"",$V37-$T37) | X37: =IF($W37="","",$W37*$O37) | Y37: =IF($A37="","",IF($T37<=0,"AGOTADO",IF($T37<=N($K37),"REORDENAR","OK"))) | Z37: =IF($A37="","",IF($T37<=N($K37),ROUNDUP((2*N($K37)-$T37)/$F37,0),0)) | AA37: =IF(OR($Y37="REORDENAR",$Y37="AGOTADO"),ROW(),"")
M38: =IF($A38="","",IFERROR($G38/$F38,0)) | N38: =IF($A38="","",IFERROR(SUMIFS(COMPRAS!$N$6:$N$1005,COMPRAS!$D$6:$D$1005,$A38,COMPRAS!$R$6:$R$1005,1)/COUNTIFS(COMPRAS!$D$6:$D$1005,$A38,COMPRAS!$R$6:$R$1005,1),0)) | O38: =IF($A38="","",IF($N38>0,$N38,$M38)) | P38: =IF($A38="","",IF(N($I38)>0,$O38/$I38,$O38)) | Q38: =IF($A38="","",SUMIFS(COMPRAS!$I$6:$I$1005,COMPRAS!$D$6:$D$1005,$A38)) | R38: =IF($A38="","",SUMIFS(RECETAS!$L$6:$L$605,RECETAS!$C$6:$C$605,$A38)) | S38: =IF($A38="","",SUMIFS(MERMAS!$J$6:$J$505,MERMAS!$B$6:$B$505,$A38)) | T38: =IF($A38="","",N($L38)+$Q38-$R38+$S38) | U38: =IF($A38="","",$T38*$O38) | W38: =IF(OR($A38="",$V38=""),"",$V38-$T38) | X38: =IF($W38="","",$W38*$O38) | Y38: =IF($A38="","",IF($T38<=0,"AGOTADO",IF($T38<=N($K38),"REORDENAR","OK"))) | Z38: =IF($A38="","",IF($T38<=N($K38),ROUNDUP((2*N($K38)-$T38)/$F38,0),0)) | AA38: =IF(OR($Y38="REORDENAR",$Y38="AGOTADO"),ROW(),"")
M39: =IF($A39="","",IFERROR($G39/$F39,0)) | N39: =IF($A39="","",IFERROR(SUMIFS(COMPRAS!$N$6:$N$1005,COMPRAS!$D$6:$D$1005,$A39,COMPRAS!$R$6:$R$1005,1)/COUNTIFS(COMPRAS!$D$6:$D$1005,$A39,COMPRAS!$R$6:$R$1005,1),0)) | O39: =IF($A39="","",IF($N39>0,$N39,$M39)) | P39: =IF($A39="","",IF(N($I39)>0,$O39/$I39,$O39)) | Q39: =IF($A39="","",SUMIFS(COMPRAS!$I$6:$I$1005,COMPRAS!$D$6:$D$1005,$A39)) | R39: =IF($A39="","",SUMIFS(RECETAS!$L$6:$L$605,RECETAS!$C$6:$C$605,$A39)) | S39: =IF($A39="","",SUMIFS(MERMAS!$J$6:$J$505,MERMAS!$B$6:$B$505,$A39)) | T39: =IF($A39="","",N($L39)+$Q39-$R39+$S39) | U39: =IF($A39="","",$T39*$O39) | W39: =IF(OR($A39="",$V39=""),"",$V39-$T39) | X39: =IF($W39="","",$W39*$O39) | Y39: =IF($A39="","",IF($T39<=0,"AGOTADO",IF($T39<=N($K39),"REORDENAR","OK"))) | Z39: =IF($A39="","",IF($T39<=N($K39),ROUNDUP((2*N($K39)-$T39)/$F39,0),0)) | AA39: =IF(OR($Y39="REORDENAR",$Y39="AGOTADO"),ROW(),"")
M40: =IF($A40="","",IFERROR($G40/$F40,0)) | N40: =IF($A40="","",IFERROR(SUMIFS(COMPRAS!$N$6:$N$1005,COMPRAS!$D$6:$D$1005,$A40,COMPRAS!$R$6:$R$1005,1)/COUNTIFS(COMPRAS!$D$6:$D$1005,$A40,COMPRAS!$R$6:$R$1005,1),0)) | O40: =IF($A40="","",IF($N40>0,$N40,$M40)) | P40: =IF($A40="","",IF(N($I40)>0,$O40/$I40,$O40)) | Q40: =IF($A40="","",SUMIFS(COMPRAS!$I$6:$I$1005,COMPRAS!$D$6:$D$1005,$A40)) | R40: =IF($A40="","",SUMIFS(RECETAS!$L$6:$L$605,RECETAS!$C$6:$C$605,$A40)) | S40: =IF($A40="","",SUMIFS(MERMAS!$J$6:$J$505,MERMAS!$B$6:$B$505,$A40)) | T40: =IF($A40="","",N($L40)+$Q40-$R40+$S40) | U40: =IF($A40="","",$T40*$O40) | W40: =IF(OR($A40="",$V40=""),"",$V40-$T40) | X40: =IF($W40="","",$W40*$O40) | Y40: =IF($A40="","",IF($T40<=0,"AGOTADO",IF($T40<=N($K40),"REORDENAR","OK"))) | Z40: =IF($A40="","",IF($T40<=N($K40),ROUNDUP((2*N($K40)-$T40)/$F40,0),0)) | AA40: =IF(OR($Y40="REORDENAR",$Y40="AGOTADO"),ROW(),"")
M41: =IF($A41="","",IFERROR($G41/$F41,0)) | N41: =IF($A41="","",IFERROR(SUMIFS(COMPRAS!$N$6:$N$1005,COMPRAS!$D$6:$D$1005,$A41,COMPRAS!$R$6:$R$1005,1)/COUNTIFS(COMPRAS!$D$6:$D$1005,$A41,COMPRAS!$R$6:$R$1005,1),0)) | O41: =IF($A41="","",IF($N41>0,$N41,$M41)) | P41: =IF($A41="","",IF(N($I41)>0,$O41/$I41,$O41)) | Q41: =IF($A41="","",SUMIFS(COMPRAS!$I$6:$I$1005,COMPRAS!$D$6:$D$1005,$A41)) | R41: =IF($A41="","",SUMIFS(RECETAS!$L$6:$L$605,RECETAS!$C$6:$C$605,$A41)) | S41: =IF($A41="","",SUMIFS(MERMAS!$J$6:$J$505,MERMAS!$B$6:$B$505,$A41)) | T41: =IF($A41="","",N($L41)+$Q41-$R41+$S41) | U41: =IF($A41="","",$T41*$O41) | W41: =IF(OR($A41="",$V41=""),"",$V41-$T41) | X41: =IF($W41="","",$W41*$O41) | Y41: =IF($A41="","",IF($T41<=0,"AGOTADO",IF($T41<=N($K41),"REORDENAR","OK"))) | Z41: =IF($A41="","",IF($T41<=N($K41),ROUNDUP((2*N($K41)-$T41)/$F41,0),0)) | AA41: =IF(OR($Y41="REORDENAR",$Y41="AGOTADO"),ROW(),"")
M42: =IF($A42="","",IFERROR($G42/$F42,0)) | N42: =IF($A42="","",IFERROR(SUMIFS(COMPRAS!$N$6:$N$1005,COMPRAS!$D$6:$D$1005,$A42,COMPRAS!$R$6:$R$1005,1)/COUNTIFS(COMPRAS!$D$6:$D$1005,$A42,COMPRAS!$R$6:$R$1005,1),0)) | O42: =IF($A42="","",IF($N42>0,$N42,$M42)) | P42: =IF($A42="","",IF(N($I42)>0,$O42/$I42,$O42)) | Q42: =IF($A42="","",SUMIFS(COMPRAS!$I$6:$I$1005,COMPRAS!$D$6:$D$1005,$A42)) | R42: =IF($A42="","",SUMIFS(RECETAS!$L$6:$L$605,RECETAS!$C$6:$C$605,$A42)) | S42: =IF($A42="","",SUMIFS(MERMAS!$J$6:$J$505,MERMAS!$B$6:$B$505,$A42)) | T42: =IF($A42="","",N($L42)+$Q42-$R42+$S42) | U42: =IF($A42="","",$T42*$O42) | W42: =IF(OR($A42="",$V42=""),"",$V42-$T42) | X42: =IF($W42="","",$W42*$O42) | Y42: =IF($A42="","",IF($T42<=0,"AGOTADO",IF($T42<=N($K42),"REORDENAR","OK"))) | Z42: =IF($A42="","",IF($T42<=N($K42),ROUNDUP((2*N($K42)-$T42)/$F42,0),0)) | AA42: =IF(OR($Y42="REORDENAR",$Y42="AGOTADO"),ROW(),"")
M43: =IF($A43="","",IFERROR($G43/$F43,0)) | N43: =IF($A43="","",IFERROR(SUMIFS(COMPRAS!$N$6:$N$1005,COMPRAS!$D$6:$D$1005,$A43,COMPRAS!$R$6:$R$1005,1)/COUNTIFS(COMPRAS!$D$6:$D$1005,$A43,COMPRAS!$R$6:$R$1005,1),0)) | O43: =IF($A43="","",IF($N43>0,$N43,$M43)) | P43: =IF($A43="","",IF(N($I43)>0,$O43/$I43,$O43)) | Q43: =IF($A43="","",SUMIFS(COMPRAS!$I$6:$I$1005,COMPRAS!$D$6:$D$1005,$A43)) | R43: =IF($A43="","",SUMIFS(RECETAS!$L$6:$L$605,RECETAS!$C$6:$C$605,$A43)) | S43: =IF($A43="","",SUMIFS(MERMAS!$J$6:$J$505,MERMAS!$B$6:$B$505,$A43)) | T43: =IF($A43="","",N($L43)+$Q43-$R43+$S43) | U43: =IF($A43="","",$T43*$O43) | W43: =IF(OR($A43="",$V43=""),"",$V43-$T43) | X43: =IF($W43="","",$W43*$O43) | Y43: =IF($A43="","",IF($T43<=0,"AGOTADO",IF($T43<=N($K43),"REORDENAR","OK"))) | Z43: =IF($A43="","",IF($T43<=N($K43),ROUNDUP((2*N($K43)-$T43)/$F43,0),0)) | AA43: =IF(OR($Y43="REORDENAR",$Y43="AGOTADO"),ROW(),"")
M44: =IF($A44="","",IFERROR($G44/$F44,0)) | N44: =IF($A44="","",IFERROR(SUMIFS(COMPRAS!$N$6:$N$1005,COMPRAS!$D$6:$D$1005,$A44,COMPRAS!$R$6:$R$1005,1)/COUNTIFS(COMPRAS!$D$6:$D$1005,$A44,COMPRAS!$R$6:$R$1005,1),0)) | O44: =IF($A44="","",IF($N44>0,$N44,$M44)) | P44: =IF($A44="","",IF(N($I44)>0,$O44/$I44,$O44)) | Q44: =IF($A44="","",SUMIFS(COMPRAS!$I$6:$I$1005,COMPRAS!$D$6:$D$1005,$A44)) | R44: =IF($A44="","",SUMIFS(RECETAS!$L$6:$L$605,RECETAS!$C$6:$C$605,$A44)) | S44: =IF($A44="","",SUMIFS(MERMAS!$J$6:$J$505,MERMAS!$B$6:$B$505,$A44)) | T44: =IF($A44="","",N($L44)+$Q44-$R44+$S44) | U44: =IF($A44="","",$T44*$O44) | W44: =IF(OR($A44="",$V44=""),"",$V44-$T44) | X44: =IF($W44="","",$W44*$O44) | Y44: =IF($A44="","",IF($T44<=0,"AGOTADO",IF($T44<=N($K44),"REORDENAR","OK"))) | Z44: =IF($A44="","",IF($T44<=N($K44),ROUNDUP((2*N($K44)-$T44)/$F44,0),0)) | AA44: =IF(OR($Y44="REORDENAR",$Y44="AGOTADO"),ROW(),"")
M45: =IF($A45="","",IFERROR($G45/$F45,0)) | N45: =IF($A45="","",IFERROR(SUMIFS(COMPRAS!$N$6:$N$1005,COMPRAS!$D$6:$D$1005,$A45,COMPRAS!$R$6:$R$1005,1)/COUNTIFS(COMPRAS!$D$6:$D$1005,$A45,COMPRAS!$R$6:$R$1005,1),0)) | O45: =IF($A45="","",IF($N45>0,$N45,$M45)) | P45: =IF($A45="","",IF(N($I45)>0,$O45/$I45,$O45)) | Q45: =IF($A45="","",SUMIFS(COMPRAS!$I$6:$I$1005,COMPRAS!$D$6:$D$1005,$A45)) | R45: =IF($A45="","",SUMIFS(RECETAS!$L$6:$L$605,RECETAS!$C$6:$C$605,$A45)) | S45: =IF($A45="","",SUMIFS(MERMAS!$J$6:$J$505,MERMAS!$B$6:$B$505,$A45)) | T45: =IF($A45="","",N($L45)+$Q45-$R45+$S45) | U45: =IF($A45="","",$T45*$O45) | W45: =IF(OR($A45="",$V45=""),"",$V45-$T45) | X45: =IF($W45="","",$W45*$O45) | Y45: =IF($A45="","",IF($T45<=0,"AGOTADO",IF($T45<=N($K45),"REORDENAR","OK"))) | Z45: =IF($A45="","",IF($T45<=N($K45),ROUNDUP((2*N($K45)-$T45)/$F45,0),0)) | AA45: =IF(OR($Y45="REORDENAR",$Y45="AGOTADO"),ROW(),"")
M46: =IF($A46="","",IFERROR($G46/$F46,0)) | N46: =IF($A46="","",IFERROR(SUMIFS(COMPRAS!$N$6:$N$1005,COMPRAS!$D$6:$D$1005,$A46,COMPRAS!$R$6:$R$1005,1)/COUNTIFS(COMPRAS!$D$6:$D$1005,$A46,COMPRAS!$R$6:$R$1005,1),0)) | O46: =IF($A46="","",IF($N46>0,$N46,$M46)) | P46: =IF($A46="","",IF(N($I46)>0,$O46/$I46,$O46)) | Q46: =IF($A46="","",SUMIFS(COMPRAS!$I$6:$I$1005,COMPRAS!$D$6:$D$1005,$A46)) | R46: =IF($A46="","",SUMIFS(RECETAS!$L$6:$L$605,RECETAS!$C$6:$C$605,$A46)) | S46: =IF($A46="","",SUMIFS(MERMAS!$J$6:$J$505,MERMAS!$B$6:$B$505,$A46)) | T46: =IF($A46="","",N($L46)+$Q46-$R46+$S46) | U46: =IF($A46="","",$T46*$O46) | W46: =IF(OR($A46="",$V46=""),"",$V46-$T46) | X46: =IF($W46="","",$W46*$O46) | Y46: =IF($A46="","",IF($T46<=0,"AGOTADO",IF($T46<=N($K46),"REORDENAR","OK"))) | Z46: =IF($A46="","",IF($T46<=N($K46),ROUNDUP((2*N($K46)-$T46)/$F46,0),0)) | AA46: =IF(OR($Y46="REORDENAR",$Y46="AGOTADO"),ROW(),"")
M47: =IF($A47="","",IFERROR($G47/$F47,0)) | N47: =IF($A47="","",IFERROR(SUMIFS(COMPRAS!$N$6:$N$1005,COMPRAS!$D$6:$D$1005,$A47,COMPRAS!$R$6:$R$1005,1)/COUNTIFS(COMPRAS!$D$6:$D$1005,$A47,COMPRAS!$R$6:$R$1005,1),0)) | O47: =IF($A47="","",IF($N47>0,$N47,$M47)) | P47: =IF($A47="","",IF(N($I47)>0,$O47/$I47,$O47)) | Q47: =IF($A47="","",SUMIFS(COMPRAS!$I$6:$I$1005,COMPRAS!$D$6:$D$1005,$A47)) | R47: =IF($A47="","",SUMIFS(RECETAS!$L$6:$L$605,RECETAS!$C$6:$C$605,$A47)) | S47: =IF($A47="","",SUMIFS(MERMAS!$J$6:$J$505,MERMAS!$B$6:$B$505,$A47)) | T47: =IF($A47="","",N($L47)+$Q47-$R47+$S47) | U47: =IF($A47="","",$T47*$O47) | W47: =IF(OR($A47="",$V47=""),"",$V47-$T47) | X47: =IF($W47="","",$W47*$O47) | Y47: =IF($A47="","",IF($T47<=0,"AGOTADO",IF($T47<=N($K47),"REORDENAR","OK"))) | Z47: =IF($A47="","",IF($T47<=N($K47),ROUNDUP((2*N($K47)-$T47)/$F47,0),0)) | AA47: =IF(OR($Y47="REORDENAR",$Y47="AGOTADO"),ROW(),"")
M48: =IF($A48="","",IFERROR($G48/$F48,0)) | N48: =IF($A48="","",IFERROR(SUMIFS(COMPRAS!$N$6:$N$1005,COMPRAS!$D$6:$D$1005,$A48,COMPRAS!$R$6:$R$1005,1)/COUNTIFS(COMPRAS!$D$6:$D$1005,$A48,COMPRAS!$R$6:$R$1005,1),0)) | O48: =IF($A48="","",IF($N48>0,$N48,$M48)) | P48: =IF($A48="","",IF(N($I48)>0,$O48/$I48,$O48)) | Q48: =IF($A48="","",SUMIFS(COMPRAS!$I$6:$I$1005,COMPRAS!$D$6:$D$1005,$A48)) | R48: =IF($A48="","",SUMIFS(RECETAS!$L$6:$L$605,RECETAS!$C$6:$C$605,$A48)) | S48: =IF($A48="","",SUMIFS(MERMAS!$J$6:$J$505,MERMAS!$B$6:$B$505,$A48)) | T48: =IF($A48="","",N($L48)+$Q48-$R48+$S48) | U48: =IF($A48="","",$T48*$O48) | W48: =IF(OR($A48="",$V48=""),"",$V48-$T48) | X48: =IF($W48="","",$W48*$O48) | Y48: =IF($A48="","",IF($T48<=0,"AGOTADO",IF($T48<=N($K48),"REORDENAR","OK"))) | Z48: =IF($A48="","",IF($T48<=N($K48),ROUNDUP((2*N($K48)-$T48)/$F48,0),0)) | AA48: =IF(OR($Y48="REORDENAR",$Y48="AGOTADO"),ROW(),"")
... M205: =IF($A205="","",IFERROR($G205/$F205,0)) | N205: =IF($A205="","",IFERROR(SUMIFS(COMPRAS!$N$6:$N$1005,COMPRAS!$D$6:$D$1005,$A205,COMPRAS!$R$6:$R$1005,1)/COUNTIFS(COMPRAS!$D$6:$D$1005,$A205,COMPRAS!$R$6:$R$1005,1),0)) | O205: =IF($A205="","",IF($N205>0,$N205,$M205)) | P205: =IF($A205="","",IF(N($I205)>0,$O205/$I205,$O205)) | Q205: =IF($A205="","",SUMIFS(COMPRAS!$I$6:$I$1005,COMPRAS!$D$6:$D$1005,$A205)) | R205: =IF($A205="","",SUMIFS(RECETAS!$L$6:$L$605,RECETAS!$C$6:$C$605,$A205)) | S205: =IF($A205="","",SUMIFS(MERMAS!$J$6:$J$505,MERMAS!$B$6:$B$505,$A205)) | T205: =IF($A205="","",N($L205)+$Q205-$R205+$S205) | U205: =IF($A205="","",$T205*$O205) | W205: =IF(OR($A205="",$V205=""),"",$V205-$T205) | X205: =IF($W205="","",$W205*$O205) | Y205: =IF($A205="","",IF($T205<=0,"AGOTADO",IF($T205<=N($K205),"REORDENAR","OK"))) | Z205: =IF($A205="","",IF($T205<=N($K205),ROUNDUP((2*N($K205)-$T205)/$F205,0),0)) | AA205: =IF(OR($Y205="REORDENAR",$Y205="AGOTADO"),ROW(),"")

Sheet COMPRAS
A1: REGISTRO DE COMPRAS A PROVEEDORES
A2: Una línea por insumo de cada factura. La cantidad se escribe en PRESENTACIONES (cajas, paquetes, latas); el libro la convierte a unidad base y la suma al inventario.
L4: Pendiente de pago: | M4: =SUMIFS(M6:M1005,P6:P1005,"Pendiente") -> 51246
A5: Fecha | B5: N° factura | C5: Proveedor | D5: Código insumo | E5: Insumo | F5: Presentación | G5: Cantidad (presenta-ciones) | H5: Contenido por presentación | I5: Cantidad en unid. base | J5: Subtotal sin IVA | K5: % IVA | L5: IVA | M5: Total factura línea | N5: Costo por unid. base | O5: Forma de pago | P5: Estado de pago | Q5: Mes | R5: Última compra del insumo (1=sí)
A6: 46296 | B6: FA-1021 | C6: Productor / feria | D6: I001 | E6: =IF($D6="","",IFERROR(INDEX(INSUMOS!$B$6:$B$205,MATCH($D6,INSUMOS!$A$6:$A$205,0)),"¿Código?")) -> Fresas frescas | F6: =IF($D6="","",IFERROR(INDEX(INSUMOS!$E$6:$E$205,MATCH($D6,INSUMOS!$A$6:$A$205,0)),"")) -> Caja 5 kg | G6: 3 | H6: =IF($D6="","",IFERROR(INDEX(INSUMOS!$F$6:$F$205,MATCH($D6,INSUMOS!$A$6:$A$205,0)),0)) -> 5000 | I6: =IF($D6="","",N($G6)*$H6) -> 15000 | J6: 42000 | K6: =IF($D6="","",IFERROR(INDEX(INSUMOS!$H$6:$H$205,MATCH($D6,INSUMOS!$A$6:$A$205,0)),IVA_VENTAS)) -> 0.01 | L6: =IF($D6="","",N($J6)*$K6) -> 420 | M6: =IF($D6="","",N($J6)+$L6) -> 42420 | N6: =IF($D6="","",IFERROR(N($J6)/$I6,0)) -> 2.8 | O6: Contado | P6: Pagado | Q6: =IF($A6="","",DATE(YEAR($A6),MONTH($A6),1)) -> 46296 | R6: =IF(OR($A6="",$D6=""),"",IF(COUNTIFS($D$6:$D$1005,$D6,$A$6:$A$1005,">"&$A6)=0,1,0)) -> 1
A7: 46296 | B7: FA-1021 | C7: Productor / feria | D7: I002 | E7: =IF($D7="","",IFERROR(INDEX(INSUMOS!$B$6:$B$205,MATCH($D7,INSUMOS!$A$6:$A$205,0)),"¿Código?")) -> Mango maduro | F7: =IF($D7="","",IFERROR(INDEX(INSUMOS!$E$6:$E$205,MATCH($D7,INSUMOS!$A$6:$A$205,0)),"")) -> Kilo | G7: 5 | H7: =IF($D7="","",IFERROR(INDEX(INSUMOS!$F$6:$F$205,MATCH($D7,INSUMOS!$A$6:$A$205,0)),0)) -> 1000 | I7: =IF($D7="","",N($G7)*$H7) -> 5000 | J7: 6500 | K7: =IF($D7="","",IFERROR(INDEX(INSUMOS!$H$6:$H$205,MATCH($D7,INSUMOS!$A$6:$A$205,0)),IVA_VENTAS)) -> 0.01 | L7: =IF($D7="","",N($J7)*$K7) -> 65 | M7: =IF($D7="","",N($J7)+$L7) -> 6565 | N7: =IF($D7="","",IFERROR(N($J7)/$I7,0)) -> 1.3 | O7: Contado | P7: Pagado | Q7: =IF($A7="","",DATE(YEAR($A7),MONTH($A7),1)) -> 46296 | R7: =IF(OR($A7="",$D7=""),"",IF(COUNTIFS($D$6:$D$1005,$D7,$A$6:$A$1005,">"&$A7)=0,1,0)) -> 1
A8: 46297 | B8: D-5530 | C8: Distribuidora lácteos | D8: I004 | E8: =IF($D8="","",IFERROR(INDEX(INSUMOS!$B$6:$B$205,MATCH($D8,INSUMOS!$A$6:$A$205,0)),"¿Código?")) -> Crema dulce | F8: =IF($D8="","",IFERROR(INDEX(INSUMOS!$E$6:$E$205,MATCH($D8,INSUMOS!$A$6:$A$205,0)),"")) -> Caja 1 L | G8: 12 | H8: =IF($D8="","",IFERROR(INDEX(INSUMOS!$F$6:$F$205,MATCH($D8,INSUMOS!$A$6:$A$205,0)),0)) -> 1000 | I8: =IF($D8="","",N($G8)*$H8) -> 12000 | J8: 30600 | K8: =IF($D8="","",IFERROR(INDEX(INSUMOS!$H$6:$H$205,MATCH($D8,INSUMOS!$A$6:$A$205,0)),IVA_VENTAS)) -> 0.01 | L8: =IF($D8="","",N($J8)*$K8) -> 306 | M8: =IF($D8="","",N($J8)+$L8) -> 30906 | N8: =IF($D8="","",IFERROR(N($J8)/$I8,0)) -> 2.55 | O8: Crédito | P8: Pendiente | Q8: =IF($A8="","",DATE(YEAR($A8),MONTH($A8),1)) -> 46296 | R8: =IF(OR($A8="",$D8=""),"",IF(COUNTIFS($D$6:$D$1005,$D8,$A$6:$A$1005,">"&$A8)=0,1,0)) -> 1
A9: 46297 | B9: M-8812 | C9: Mayorista | D9: I005 | E9: =IF($D9="","",IFERROR(INDEX(INSUMOS!$B$6:$B$205,MATCH($D9,INSUMOS!$A$6:$A$205,0)),"¿Código?")) -> Leche condensada | F9: =IF($D9="","",IFERROR(INDEX(INSUMOS!$E$6:$E$205,MATCH($D9,INSUMOS!$A$6:$A$205,0)),"")) -> Lata 397 g | G9: 24 | H9: =IF($D9="","",IFERROR(INDEX(INSUMOS!$F$6:$F$205,MATCH($D9,INSUMOS!$A$6:$A$205,0)),0)) -> 397 | I9: =IF($D9="","",N($G9)*$H9) -> 9528 | J9: 30000 | K9: =IF($D9="","",IFERROR(INDEX(INSUMOS!$H$6:$H$205,MATCH($D9,INSUMOS!$A$6:$A$205,0)),IVA_VENTAS)) -> 0.13 | L9: =IF($D9="","",N($J9)*$K9) -> 3900 | M9: =IF($D9="","",N($J9)+$L9) -> 33900 | N9: =IF($D9="","",IFERROR(N($J9)/$I9,0)) -> 3.1486146 | O9: Contado | P9: Pagado | Q9: =IF($A9="","",DATE(YEAR($A9),MONTH($A9),1)) -> 46296 | R9: =IF(OR($A9="",$D9=""),"",IF(COUNTIFS($D$6:$D$1005,$D9,$A$6:$A$1005,">"&$A9)=0,1,0)) -> 1
A10: 46297 | B10: M-8812 | C10: Mayorista | D10: I008 | E10: =IF($D10="","",IFERROR(INDEX(INSUMOS!$B$6:$B$205,MATCH($D10,INSUMOS!$A$6:$A$205,0)),"¿Código?")) -> Galleta Oreo triturada | F10: =IF($D10="","",IFERROR(INDEX(INSUMOS!$E$6:$E$205,MATCH($D10,INSUMOS!$A$6:$A$205,0)),"")) -> Paquete 432 g | G10: 4 | H10: =IF($D10="","",IFERROR(INDEX(INSUMOS!$F$6:$F$205,MATCH($D10,INSUMOS!$A$6:$A$205,0)),0)) -> 432 | I10: =IF($D10="","",N($G10)*$H10) -> 1728 | J10: 10400 | K10: =IF($D10="","",IFERROR(INDEX(INSUMOS!$H$6:$H$205,MATCH($D10,INSUMOS!$A$6:$A$205,0)),IVA_VENTAS)) -> 0.13 | L10: =IF($D10="","",N($J10)*$K10) -> 1352 | M10: =IF($D10="","",N($J10)+$L10) -> 11752 | N10: =IF($D10="","",IFERROR(N($J10)/$I10,0)) -> 6.0185185 | O10: Contado | P10: Pagado | Q10: =IF($A10="","",DATE(YEAR($A10),MONTH($A10),1)) -> 46296 | R10: =IF(OR($A10="",$D10=""),"",IF(COUNTIFS($D$6:$D$1005,$D10,$A$6:$A$1005,">"&$A10)=0,1,0)) -> 1
A11: 46298 | B11: E-0099 | C11: Empaques CR | D11: I021 | E11: =IF($D11="","",IFERROR(INDEX(INSUMOS!$B$6:$B$205,MATCH($D11,INSUMOS!$A$6:$A$205,0)),"¿Código?")) -> Vaso 12 oz con tapa | F11: =IF($D11="","",IFERROR(INDEX(INSUMOS!$E$6:$E$205,MATCH($D11,INSUMOS!$A$6:$A$205,0)),"")) -> Paquete 50 u | G11: 4 | H11: =IF($D11="","",IFERROR(INDEX(INSUMOS!$F$6:$F$205,MATCH($D11,INSUMOS!$A$6:$A$205,0)),0)) -> 50 | I11: =IF($D11="","",N($G11)*$H11) -> 200 | J11: 18000 | K11: =IF($D11="","",IFERROR(INDEX(INSUMOS!$H$6:$H$205,MATCH($D11,INSUMOS!$A$6:$A$205,0)),IVA_VENTAS)) -> 0.13 | L11: =IF($D11="","",N($J11)*$K11) -> 2340 | M11: =IF($D11="","",N($J11)+$L11) -> 20340 | N11: =IF($D11="","",IFERROR(N($J11)/$I11,0)) -> 90 | O11: Crédito | P11: Pendiente | Q11: =IF($A11="","",DATE(YEAR($A11),MONTH($A11),1)) -> 46296 | R11: =IF(OR($A11="",$D11=""),"",IF(COUNTIFS($D$6:$D$1005,$D11,$A$6:$A$1005,">"&$A11)=0,1,0)) -> 1
E12: =IF($D12="","",IFERROR(INDEX(INSUMOS!$B$6:$B$205,MATCH($D12,INSUMOS!$A$6:$A$205,0)),"¿Código?")) | F12: =IF($D12="","",IFERROR(INDEX(INSUMOS!$E$6:$E$205,MATCH($D12,INSUMOS!$A$6:$A$205,0)),"")) | H12: =IF($D12="","",IFERROR(INDEX(INSUMOS!$F$6:$F$205,MATCH($D12,INSUMOS!$A$6:$A$205,0)),0)) | I12: =IF($D12="","",N($G12)*$H12) | K12: =IF($D12="","",IFERROR(INDEX(INSUMOS!$H$6:$H$205,MATCH($D12,INSUMOS!$A$6:$A$205,0)),IVA_VENTAS)) | L12: =IF($D12="","",N($J12)*$K12) | M12: =IF($D12="","",N($J12)+$L12) | N12: =IF($D12="","",IFERROR(N($J12)/$I12,0)) | Q12: =IF($A12="","",DATE(YEAR($A12),MONTH($A12),1)) | R12: =IF(OR($A12="",$D12=""),"",IF(COUNTIFS($D$6:$D$1005,$D12,$A$6:$A$1005,">"&$A12)=0,1,0))
E13: =IF($D13="","",IFERROR(INDEX(INSUMOS!$B$6:$B$205,MATCH($D13,INSUMOS!$A$6:$A$205,0)),"¿Código?")) | F13: =IF($D13="","",IFERROR(INDEX(INSUMOS!$E$6:$E$205,MATCH($D13,INSUMOS!$A$6:$A$205,0)),"")) | H13: =IF($D13="","",IFERROR(INDEX(INSUMOS!$F$6:$F$205,MATCH($D13,INSUMOS!$A$6:$A$205,0)),0)) | I13: =IF($D13="","",N($G13)*$H13) | K13: =IF($D13="","",IFERROR(INDEX(INSUMOS!$H$6:$H$205,MATCH($D13,INSUMOS!$A$6:$A$205,0)),IVA_VENTAS)) | L13: =IF($D13="","",N($J13)*$K13) | M13: =IF($D13="","",N($J13)+$L13) | N13: =IF($D13="","",IFERROR(N($J13)/$I13,0)) | Q13: =IF($A13="","",DATE(YEAR($A13),MONTH($A13),1)) | R13: =IF(OR($A13="",$D13=""),"",IF(COUNTIFS($D$6:$D$1005,$D13,$A$6:$A$1005,">"&$A13)=0,1,0))
E14: =IF($D14="","",IFERROR(INDEX(INSUMOS!$B$6:$B$205,MATCH($D14,INSUMOS!$A$6:$A$205,0)),"¿Código?")) | F14: =IF($D14="","",IFERROR(INDEX(INSUMOS!$E$6:$E$205,MATCH($D14,INSUMOS!$A$6:$A$205,0)),"")) | H14: =IF($D14="","",IFERROR(INDEX(INSUMOS!$F$6:$F$205,MATCH($D14,INSUMOS!$A$6:$A$205,0)),0)) | I14: =IF($D14="","",N($G14)*$H14) | K14: =IF($D14="","",IFERROR(INDEX(INSUMOS!$H$6:$H$205,MATCH($D14,INSUMOS!$A$6:$A$205,0)),IVA_VENTAS)) | L14: =IF($D14="","",N($J14)*$K14) | M14: =IF($D14="","",N($J14)+$L14) | N14: =IF($D14="","",IFERROR(N($J14)/$I14,0)) | Q14: =IF($A14="","",DATE(YEAR($A14),MONTH($A14),1)) | R14: =IF(OR($A14="",$D14=""),"",IF(COUNTIFS($D$6:$D$1005,$D14,$A$6:$A$1005,">"&$A14)=0,1,0))
E15: =IF($D15="","",IFERROR(INDEX(INSUMOS!$B$6:$B$205,MATCH($D15,INSUMOS!$A$6:$A$205,0)),"¿Código?")) | F15: =IF($D15="","",IFERROR(INDEX(INSUMOS!$E$6:$E$205,MATCH($D15,INSUMOS!$A$6:$A$205,0)),"")) | H15: =IF($D15="","",IFERROR(INDEX(INSUMOS!$F$6:$F$205,MATCH($D15,INSUMOS!$A$6:$A$205,0)),0)) | I15: =IF($D15="","",N($G15)*$H15) | K15: =IF($D15="","",IFERROR(INDEX(INSUMOS!$H$6:$H$205,MATCH($D15,INSUMOS!$A$6:$A$205,0)),IVA_VENTAS)) | L15: =IF($D15="","",N($J15)*$K15) | M15: =IF($D15="","",N($J15)+$L15) | N15: =IF($D15="","",IFERROR(N($J15)/$I15,0)) | Q15: =IF($A15="","",DATE(YEAR($A15),MONTH($A15),1)) | R15: =IF(OR($A15="",$D15=""),"",IF(COUNTIFS($D$6:$D$1005,$D15,$A$6:$A$1005,">"&$A15)=0,1,0))
